<?xml version="1.0" ?>
<robot name="ur5" xmlns:xacro="http://ros.org/wiki/xacro">
    <gazebo>
        <plugin filename="libgazebo_ros_control.so" name="ros_control">
            <!--robotNamespace>/</robotNamespace-->
            <!--robotSimType>gazebo_ros_control/DefaultRobotHWSim</robotSimType-->
        </plugin>
    </gazebo>
    <link name="right_base_link">
        <visual>
            <origin rpy="0 0 3.14159265359" xyz="0 0 0" />
            <geometry>
                <mesh filename="package://ur_description/meshes/ur5/visual/base.dae" />
            </geometry>
            <material name="LightGrey">
                <color rgba="0.7 0.7 0.7 1.0" />
            </material>
        </visual>
        <collision>
            <origin rpy="0 0 3.14159265359" xyz="0 0 0" />
            <geometry>
                <mesh filename="package://ur_description/meshes/ur5/collision/base.stl" />
            </geometry>
        </collision>
        
<inertial>
            <mass value="4.0" />
            <origin rpy="0 0 0" xyz="0.0 0.0 0.0" />
            <inertia ixx="0.00443333156" ixy="0.0" ixz="0.0" iyy="0.00443333156" iyz="0.0" izz="0.0072" />
        </inertial>

    </link>
    <joint name="right_shoulder_pan_joint" type="revolute">
        <parent link="right_base_link" />
        <child link="right_shoulder_link" />
        <origin rpy="0 0 3.14159265359" xyz="0 0 0.089159" />
        <axis xyz="0 0 1" />
        <limit effort="150.0" lower="-3.14159265359" upper="3.14159265359" velocity="3.15" />
        <dynamics damping="0.0" friction="0.0" />
    </joint>
    <link name="right_shoulder_link">
        <visual>
            <origin rpy="0 0 3.14159265359" xyz="0 0 0" />
            <geometry>
                <mesh filename="package://ur_description/meshes/ur5/visual/shoulder.dae" />
            </geometry>
            <material name="LightGrey">
                <color rgba="0.7 0.7 0.7 1.0" />
            </material>
        </visual>
        <collision>
            <origin rpy="0 0 3.14159265359" xyz="0 0 0" />
            <geometry>
                <mesh filename="package://ur_description/meshes/ur5/collision/shoulder.stl" />
            </geometry>
        </collision>
        
<inertial>
            <mass value="3.7" />
            <origin rpy="0 0 0" xyz="0.0 0.0 0.0" />
            <inertia ixx="0.0149723523444" ixy="0.0" ixz="0.0" iyy="0.0149723523444" iyz="0.0" izz="0.01040625" />
        </inertial>

    </link>
    <joint name="right_shoulder_lift_joint" type="revolute">
        <parent link="right_shoulder_link" />
        <child link="right_upper_arm_link" />
        <origin rpy="1.57079632679 0 0" xyz="0 0 0" />
        <axis xyz="0 0 1" />
        <limit effort="150.0" lower="-3.14159265359" upper="3.14159265359" velocity="3.15" />
        <dynamics damping="0.0" friction="0.0" />
    </joint>
    <link name="right_upper_arm_link">
        <visual>
            <origin rpy="1.57079632679 0 -1.57079632679" xyz="0 0 0.136" />
            <geometry>
                <mesh filename="package://ur_description/meshes/ur5/visual/upperarm.dae" />
            </geometry>
            <material name="LightGrey">
                <color rgba="0.7 0.7 0.7 1.0" />
            </material>
        </visual>
        <collision>
            <origin rpy="1.57079632679 0 -1.57079632679" xyz="0 0 0.136" />
            <geometry>
                <mesh filename="package://ur_description/meshes/ur5/collision/upperarm.stl" />
            </geometry>
        </collision>
        
<inertial>
            <mass value="8.393" />
            <origin rpy="0 1.57079632679 0" xyz="-0.2125 0.0 0.136" />
            <inertia ixx="0.133885781862" ixy="0.0" ixz="0.0" iyy="0.133885781862" iyz="0.0" izz="0.0151074" />
        </inertial>

    </link>
    <joint name="right_elbow_joint" type="revolute">
        <parent link="right_upper_arm_link" />
        <child link="right_forearm_link" />
        <origin rpy="0.0 0.0 0.0" xyz="-0.425 0 0" />
        <axis xyz="0 0 1" />
        <limit effort="150.0" lower="-3.14159265359" upper="3.14159265359" velocity="3.15" />
        <dynamics damping="0.0" friction="0.0" />
    </joint>
    <link name="right_forearm_link">
        <visual>
            <origin rpy="1.57079632679 0 -1.57079632679" xyz="0 0 0.0165" />
            <geometry>
                <mesh filename="package://ur_description/meshes/ur5/visual/forearm.dae" />
            </geometry>
            <material name="LightGrey">
                <color rgba="0.7 0.7 0.7 1.0" />
            </material>
        </visual>
        <collision>
            <origin rpy="1.57079632679 0 -1.57079632679" xyz="0 0 0.0165" />
            <geometry>
                <mesh filename="package://ur_description/meshes/ur5/collision/forearm.stl" />
            </geometry>
        </collision>
        
<inertial>
            <mass value="2.275" />
            <origin rpy="0 1.57079632679 0" xyz="-0.2125 0.0 0.136" />
            <inertia ixx="0.0312167910289" ixy="0.0" ixz="0.0" iyy="0.0312167910289" iyz="0.0" izz="0.004095" />
        </inertial>

    </link>
    <joint name="right_wrist_1_joint" type="revolute">
        <parent link="right_forearm_link" />
        <child link="right_wrist_1_link" />
        <origin rpy="0 0 0" xyz="-0.39225 0 0.10915" />
        <axis xyz="0 0 1" />
        <limit effort="28.0" lower="-3.14159265359" upper="3.14159265359" velocity="3.2" />
        <dynamics damping="0.0" friction="0.0" />
    </joint>
    <link name="right_wrist_1_link">
        <visual>
            <origin rpy="1.57079632679 0 0" xyz="0 0 -0.093" />
            <geometry>
                <mesh filename="package://ur_description/meshes/ur5/visual/wrist1.dae" />
            </geometry>
            <material name="LightGrey">
                <color rgba="0.7 0.7 0.7 1.0" />
            </material>
        </visual>
        <collision>
            <origin rpy="1.57079632679 0 0" xyz="0 0 -0.093" />
            <geometry>
                <mesh filename="package://ur_description/meshes/ur5/collision/wrist1.stl" />
            </geometry>
        </collision>
        
<inertial>
            <mass value="1.219" />
            <origin rpy="0 0 0" xyz="0.0 0.0 0.0" />
            <inertia ixx="0.00262426443592" ixy="0.0" ixz="0.0" iyy="0.00262426443592" iyz="0.0" izz="0.0034284375" />
        </inertial>

    </link>
    <joint name="right_wrist_2_joint" type="revolute">
        <parent link="right_wrist_1_link" />
        <child link="right_wrist_2_link" />
        <origin rpy="1.570796327 0 0" xyz="0 -0.09465 -1.9413039509e-11" />
        <axis xyz="0 0 1" />
        <limit effort="28.0" lower="-3.14159265359" upper="3.14159265359" velocity="3.2" />
        <dynamics damping="0.0" friction="0.0" />
    </joint>
    <link name="right_wrist_2_link">
        <visual>
            <origin rpy="0 0 0" xyz="0 0 -0.095" />
            <geometry>
                <mesh filename="package://ur_description/meshes/ur5/visual/wrist2.dae" />
            </geometry>
            <material name="LightGrey">
                <color rgba="0.7 0.7 0.7 1.0" />
            </material>
        </visual>
        <collision>
            <origin rpy="0 0 0" xyz="0 0 -0.095" />
            <geometry>
                <mesh filename="package://ur_description/meshes/ur5/collision/wrist2.stl" />
            </geometry>
        </collision>
        
<inertial>
            <mass value="1.219" />
            <origin rpy="0 0 0" xyz="0.0 0.0 0.0" />
            <inertia ixx="0.00178515266177" ixy="0.0" ixz="0.0" iyy="0.00178515266177" iyz="0.0" izz="0.0021942" />
        </inertial>

    </link>
    <joint name="right_wrist_3_joint" type="revolute">
        <parent link="right_wrist_2_link" />
        <child link="right_wrist_3_link" />
        <origin rpy="1.57079632659 3.14159265359 3.14159265359" xyz="0 0.0823 -1.68800121668e-11" />
        <axis xyz="0 0 1" />
        <limit effort="28.0" lower="-3.14159265359" upper="3.14159265359" velocity="3.2" />
        <dynamics damping="0.0" friction="0.0" />
    </joint>
    <link name="right_wrist_3_link">
        <visual>
            <origin rpy="1.57079632679 0 0" xyz="0 0 -0.0818" />
            <geometry>
                <mesh filename="package://ur_description/meshes/ur5/visual/wrist3.dae" />
            </geometry>
            <material name="LightGrey">
                <color rgba="0.7 0.7 0.7 1.0" />
            </material>
        </visual>
        <collision>
            <origin rpy="1.57079632679 0 0" xyz="0 0 -0.0818" />
            <geometry>
                <mesh filename="package://ur_description/meshes/ur5/collision/wrist3.stl" />
            </geometry>
        </collision>
        
<inertial>
            <mass value="0.1879" />
            <origin rpy="0 0 0" xyz="0.0 0.0 -0.01525" />
            <inertia ixx="8.06247260834e-05" ixy="0.0" ixz="0.0" iyy="8.06247260834e-05" iyz="0.0" izz="0.0001321171875" />
        </inertial>

    </link>
    <joint name="right_ee_fixed_joint" type="fixed">
        <parent link="right_wrist_3_link" />
        <child link="right_ee_link" />
        <origin rpy="0.0 -1.57079632679 1.57079632679" xyz="0.0 0.0 0.0" />
    </joint>
    <link name="right_ee_link">
        <collision>
            <geometry>
                <box size="0.01 0.01 0.01" />
            </geometry>
            <origin rpy="0 0 0" xyz="-0.01 0 0" />
        </collision>
        
<inertial>
            <mass value="0.1" />
            <inertia ixx="0.03" iyy="0.03" izz="0.03" ixy="0.0" ixz="0.0" iyz="0.0" />
        </inertial>

    </link>
    <transmission name="right_shoulder_pan_trans">
        <type>transmission_interface/SimpleTransmission</type>
        <joint name="right_shoulder_pan_joint">
            <hardwareInterface>hardware_interface/PositionJointInterface</hardwareInterface>
        </joint>
        <actuator name="right_shoulder_pan_motor">
            <mechanicalReduction>1</mechanicalReduction>
        </actuator>
    </transmission>
    <transmission name="right_shoulder_lift_trans">
        <type>transmission_interface/SimpleTransmission</type>
        <joint name="right_shoulder_lift_joint">
            <hardwareInterface>hardware_interface/PositionJointInterface</hardwareInterface>
        </joint>
        <actuator name="right_shoulder_lift_motor">
            <mechanicalReduction>1</mechanicalReduction>
        </actuator>
    </transmission>
    <transmission name="right_elbow_trans">
        <type>transmission_interface/SimpleTransmission</type>
        <joint name="right_elbow_joint">
            <hardwareInterface>hardware_interface/PositionJointInterface</hardwareInterface>
        </joint>
        <actuator name="right_elbow_motor">
            <mechanicalReduction>1</mechanicalReduction>
        </actuator>
    </transmission>
    <transmission name="right_wrist_1_trans">
        <type>transmission_interface/SimpleTransmission</type>
        <joint name="right_wrist_1_joint">
            <hardwareInterface>hardware_interface/PositionJointInterface</hardwareInterface>
        </joint>
        <actuator name="right_wrist_1_motor">
            <mechanicalReduction>1</mechanicalReduction>
        </actuator>
    </transmission>
    <transmission name="right_wrist_2_trans">
        <type>transmission_interface/SimpleTransmission</type>
        <joint name="right_wrist_2_joint">
            <hardwareInterface>hardware_interface/PositionJointInterface</hardwareInterface>
        </joint>
        <actuator name="right_wrist_2_motor">
            <mechanicalReduction>1</mechanicalReduction>
        </actuator>
    </transmission>
    <transmission name="right_wrist_3_trans">
        <type>transmission_interface/SimpleTransmission</type>
        <joint name="right_wrist_3_joint">
            <hardwareInterface>hardware_interface/PositionJointInterface</hardwareInterface>
        </joint>
        <actuator name="right_wrist_3_motor">
            <mechanicalReduction>1</mechanicalReduction>
        </actuator>
    </transmission>
    <gazebo reference="right_shoulder_link">
        <selfCollide>true</selfCollide>
    </gazebo>
    <gazebo reference="right_upper_arm_link">
        <selfCollide>true</selfCollide>
    </gazebo>
    <gazebo reference="right_forearm_link">
        <selfCollide>true</selfCollide>
    </gazebo>
    <gazebo reference="right_wrist_1_link">
        <selfCollide>true</selfCollide>
    </gazebo>
    <gazebo reference="right_wrist_3_link">
        <selfCollide>true</selfCollide>
    </gazebo>
    <gazebo reference="right_wrist_2_link">
        <selfCollide>true</selfCollide>
    </gazebo>
    <gazebo reference="right_ee_link">
        <selfCollide>true</selfCollide>
    </gazebo>
    <!-- ROS base_link to UR 'Base' Coordinates transform -->
    <link name="right_base" />
    <joint name="right_base_link-base_fixed_joint" type="fixed">
        <!-- NOTE: this rotation is only needed as long as base_link itself is
                 not corrected wrt the real robot (ie: rotated over 180
                 degrees)
      -->
        <origin rpy="0 0 -3.14159265359" xyz="0 0 0" />
        <parent link="right_base_link" />
        <child link="right_base" />
    </joint>
    <!-- Frame coincident with all-zeros TCP on UR controller -->
    <link name="right_tool0" />
    <joint name="right_wrist_3_link-tool0_fixed_joint" type="fixed">
        <origin rpy="-1.57079632679 0 0" xyz="0 0.0823 0" />
        <parent link="right_wrist_3_link" />
        <child link="right_tool0" />
    </joint>
    <link name="world" />
    <link name="ur5_frame">
        <visual>
            <origin rpy="0.0 0 0" xyz="0 0 0" />
            <geometry>
                <mesh filename="package://daurar_description/meshes/Dual_Arm_UR5Frame.STL" />
            </geometry>
        </visual>
        <collision>
            <origin rpy="0.0 0 0" xyz="0 0 0" />
            <geometry>
                <mesh filename="package://daurar_description/meshes/Dual_Arm_UR5Frame.STL" />
            </geometry>
        </collision>
        
<inertial>
            <origin rpy="0.0 0 0" xyz="0 0 0" />
            <mass value="27.2155" />
            <inertia ixx="5.01" ixy="0.0" ixz="0.0" iyy="5.07" iyz="0.0" izz="3.20" />
        </inertial>

    </link>
    <joint name="ur5_frame_to_world" type="fixed">
        <parent link="world" />
        <child link="ur5_frame" />
        <origin rpy="0.0 0.0 0.0" xyz="0.0 0.0 0.0" />
    </joint>
    <!-- right arm -->
    <joint name="world_joint_2" type="fixed">
        <parent link="ur5_frame" />
        <child link="right_base_link" />
        <origin rpy="-0.785398163397 3.14159265359  1.57079632679" xyz="0.265 0.635 1.275" />
    </joint>
    <link name="right_gripper_base_link">
        <visual>
            <geometry>
                <mesh filename="package://robotiq_85_description/meshes/visual/robotiq_85_base_link.dae" />
            </geometry>
        </visual>
        <collision>
            <geometry>
                <mesh filename="package://robotiq_85_description/meshes/collision/robotiq_85_base_link.stl" />
            </geometry>
        </collision>
        
<inertial>
            <mass value="0.636951" />
            <origin xyz="0.0 0.0 0.0" />
            <inertia ixx="0.000380" ixy="0.000000" ixz="0.000000" iyx="0.000000" iyy="0.001110" iyz="0.000000" izx="0.000000" izy="0.000000" izz="0.001171" />
        </inertial>

    </link>
    <joint name="right_gripper_base_joint" type="fixed">
        <parent link="right_ee_link" />
        <child link="right_gripper_base_link" />
        <origin rpy="0 0 0" xyz="0 0 0" />
    </joint>
    <gazebo reference="right_gripper_base_link">
        <implicitSpringDamper>1</implicitSpringDamper>
        <mu1>100000</mu1>
        <mu2>100000</mu2>
        <kp>100000000.0</kp>
        <kd>1.0</kd>
    </gazebo>
    <joint name="right_gripper_finger1_joint" type="revolute">
        <parent link="right_gripper_base_link" />
        <child link="right_gripper_finger1_knuckle_link" />
        <axis xyz="0 0 1" />
        <origin rpy="3.14159265359 0.0 0.0" xyz="0.05490451627 0.03060114443 0.0" />
        <limit effort="1000" lower="0.0" upper="0.804" velocity="2.0" />
    </joint>
    <joint name="right_gripper_finger2_joint" type="revolute">
        <parent link="right_gripper_base_link" />
        <child link="right_gripper_finger2_knuckle_link" />
        <axis xyz="0 0 1" />
        <origin rpy="0.0 0.0 0.0" xyz="0.05490451627 -0.03060114443 0.0" />
        <limit effort="1000" lower="-3.14" upper="3.14" velocity="100.0" />
        <mimic joint="right_gripper_finger1_joint" />
    </joint>
    <link name="right_gripper_finger1_knuckle_link">
        <visual>
            <geometry>
                <mesh filename="package://robotiq_85_description/meshes/visual/robotiq_85_knuckle_link.dae" />
            </geometry>
        </visual>
        <collision>
            <geometry>
                <mesh filename="package://robotiq_85_description/meshes/collision/robotiq_85_knuckle_link.stl" />
            </geometry>
        </collision>
        
<inertial>
            <mass value="0.018491" />
            <origin xyz="0.0 0.0 0.0" />
            <inertia ixx="0.000009" ixy="-0.000001" ixz="0.000000" iyx="-0.000001" iyy="0.000001" iyz="0.000000" izx="0.000000" izy="0.000000" izz="0.000010" />
        </inertial>

    </link>
    <gazebo reference="right_gripper_finger1_knuckle_link">
        <implicitSpringDamper>1</implicitSpringDamper>
        <mu1>100000</mu1>
        <mu2>100000</mu2>
        <kp>100000000.0</kp>
        <kd>1.0</kd>
    </gazebo>
    <link name="right_gripper_finger2_knuckle_link">
        <visual>
            <geometry>
                <mesh filename="package://robotiq_85_description/meshes/visual/robotiq_85_knuckle_link.dae" />
            </geometry>
        </visual>
        <collision>
            <geometry>
                <mesh filename="package://robotiq_85_description/meshes/collision/robotiq_85_knuckle_link.stl" />
            </geometry>
        </collision>
        
<inertial>
            <mass value="0.018491" />
            <origin xyz="0.0 0.0 0.0" />
            <inertia ixx="0.000009" ixy="-0.000001" ixz="0.000000" iyx="-0.000001" iyy="0.000001" iyz="0.000000" izx="0.000000" izy="0.000000" izz="0.000010" />
        </inertial>

    </link>
    <gazebo reference="right_gripper_finger2_knuckle_link">
        <implicitSpringDamper>1</implicitSpringDamper>
        <mu1>100000</mu1>
        <mu2>100000</mu2>
        <kp>100000000.0</kp>
        <kd>1.0</kd>
    </gazebo>
    <joint name="right_gripper_finger1_finger_joint" type="fixed">
        <parent link="right_gripper_finger1_knuckle_link" />
        <child link="right_gripper_finger1_finger_link" />
        <origin rpy="0 0 0" xyz="-0.00408552455 -0.03148604435 0.0" />
    </joint>
    <joint name="right_gripper_finger2_finger_joint" type="fixed">
        <parent link="right_gripper_finger2_knuckle_link" />
        <child link="right_gripper_finger2_finger_link" />
        <origin rpy="0 0 0" xyz="-0.00408552455 -0.03148604435 0.0" />
    </joint>
    <link name="right_gripper_finger1_finger_link">
        <visual>
            <geometry>
                <mesh filename="package://robotiq_85_description/meshes/visual/robotiq_85_finger_link.dae" />
            </geometry>
        </visual>
        <collision>
            <geometry>
                <mesh filename="package://robotiq_85_description/meshes/collision/robotiq_85_finger_link.stl" />
            </geometry>
        </collision>
        
<inertial>
            <mass value="0.027309" />
            <origin xyz="0.0 0.0 0.0" />
            <inertia ixx="0.000003" ixy="-0.000002" ixz="0.000000" iyx="-0.000002" iyy="0.000021" iyz="0.000000" izx="0.000000" izy="0.000000" izz="0.000020" />
        </inertial>

    </link>
    <gazebo reference="right_gripper_finger1_finger_link">
        <implicitSpringDamper>1</implicitSpringDamper>
        <mu1>100000</mu1>
        <mu2>100000</mu2>
        <kp>100000000.0</kp>
        <kd>1.0</kd>
    </gazebo>
    <link name="right_gripper_finger2_finger_link">
        <visual>
            <geometry>
                <mesh filename="package://robotiq_85_description/meshes/visual/robotiq_85_finger_link.dae" />
            </geometry>
        </visual>
        <collision>
            <geometry>
                <mesh filename="package://robotiq_85_description/meshes/collision/robotiq_85_finger_link.stl" />
            </geometry>
        </collision>
        
<inertial>
            <mass value="0.027309" />
            <origin xyz="0.0 0.0 0.0" />
            <inertia ixx="0.000003" ixy="-0.000002" ixz="0.000000" iyx="-0.000002" iyy="0.000021" iyz="0.000000" izx="0.000000" izy="0.000000" izz="0.000020" />
        </inertial>

    </link>
    <gazebo reference="right_gripper_finger2_finger_link">
        <implicitSpringDamper>1</implicitSpringDamper>
        <mu1>100000</mu1>
        <mu2>100000</mu2>
        <kp>100000000.0</kp>
        <kd>1.0</kd>
    </gazebo>
    <joint name="right_gripper_finger1_inner_knuckle_joint" type="continuous">
        <parent link="right_gripper_base_link" />
        <child link="right_gripper_finger1_inner_knuckle_link" />
        <axis xyz="0 0 1" />
        <origin rpy="3.14159265359 0.0 0.0" xyz="0.06142 0.0127 0" />
        <limit effort="0.1" lower="-3.14" upper="3.14" velocity="100.0" />
        <mimic joint="right_gripper_finger1_joint" offset="0" />
    </joint>
    <joint name="right_gripper_finger2_inner_knuckle_joint" type="continuous">
        <parent link="right_gripper_base_link" />
        <child link="right_gripper_finger2_inner_knuckle_link" />
        <axis xyz="0 0 1" />
        <origin rpy="0 0 0" xyz="0.06142 -0.0127 0" />
        <limit effort="0.1" lower="-3.14" upper="3.14" velocity="100.0" />
        <mimic joint="right_gripper_finger1_joint" offset="0" />
    </joint>
    <link name="right_gripper_finger1_inner_knuckle_link">
        <visual>
            <geometry>
                <mesh filename="package://robotiq_85_description/meshes/visual/robotiq_85_inner_knuckle_link.dae" />
            </geometry>
        </visual>
        <collision>
            <geometry>
                <mesh filename="package://robotiq_85_description/meshes/collision/robotiq_85_inner_knuckle_link.stl" />
            </geometry>
        </collision>
        
<inertial>
            <mass value="0.029951" />
            <origin xyz="0.0 0.0 0.0" />
            <inertia ixx="0.000039" ixy="0.000000" ixz="0.000000" iyx="0.000000" iyy="0.000005" iyz="0.000000" izx="0.000000" izy="0.000000" izz="0.000035" />
        </inertial>

    </link>
    <gazebo reference="right_gripper_finger1_inner_knuckle_link">
        <implicitSpringDamper>1</implicitSpringDamper>
        <mu1>100000</mu1>
        <mu2>100000</mu2>
        <kp>100000000.0</kp>
        <kd>1.0</kd>
    </gazebo>
    <link name="right_gripper_finger2_inner_knuckle_link">
        <visual>
            <geometry>
                <mesh filename="package://robotiq_85_description/meshes/visual/robotiq_85_inner_knuckle_link.dae" />
            </geometry>
        </visual>
        <collision>
            <geometry>
                <mesh filename="package://robotiq_85_description/meshes/collision/robotiq_85_inner_knuckle_link.stl" />
            </geometry>
        </collision>
        
<inertial>
            <mass value="0.029951" />
            <origin xyz="0.0 0.0 0.0" />
            <inertia ixx="0.000039" ixy="0.000000" ixz="0.000000" iyx="0.000000" iyy="0.000005" iyz="0.000000" izx="0.000000" izy="0.000000" izz="0.000035" />
        </inertial>

    </link>
    <gazebo reference="right_gripper_finger2_inner_knuckle_link">
        <implicitSpringDamper>1</implicitSpringDamper>
        <mu1>100000</mu1>
        <mu2>100000</mu2>
        <kp>100000000.0</kp>
        <kd>1.0</kd>
    </gazebo>
    <joint name="right_gripper_finger1_finger_tip_joint" type="continuous">
        <parent link="right_gripper_finger1_inner_knuckle_link" />
        <child link="right_gripper_finger1_finger_tip_link" />
        <axis xyz="0 0 1" />
        <origin rpy="0.0 0.0 0.0" xyz="0.04303959807 -0.03759940821 0.0" />
        <limit effort="0.1" lower="-3.14" upper="3.14" velocity="100.0" />
        <mimic joint="right_gripper_finger1_joint" multiplier="-1" />
    </joint>
    <joint name="right_gripper_finger2_finger_tip_joint" type="continuous">
        <parent link="right_gripper_finger2_inner_knuckle_link" />
        <child link="right_gripper_finger2_finger_tip_link" />
        <axis xyz="0 0 1" />
        <origin rpy="0.0 0.0 0.0" xyz="0.04303959807 -0.03759940821  0.0" />
        <limit effort="0.1" lower="-3.14" upper="3.14" velocity="100.0" />
        <mimic joint="right_gripper_finger1_joint" multiplier="-1" />
    </joint>
    <link name="right_gripper_finger1_finger_tip_link">
        <visual>
            <geometry>
                <mesh filename="package://robotiq_85_description/meshes/visual/robotiq_85_finger_tip_link.dae" />
            </geometry>
        </visual>
        <collision>
            <geometry>
                <mesh filename="package://robotiq_85_description/meshes/collision/robotiq_85_finger_tip_link.stl" />
            </geometry>
        </collision>
        
<inertial>
            <mass value="0.019555" />
            <origin xyz="0.0 0.0 0.0" />
            <inertia ixx="0.000002" ixy="0.000000" ixz="0.000000" iyx="0.000000" iyy="0.000005" iyz="0.000000" izx="0.000000" izy="0.000000" izz="0.000006" />
        </inertial>

    </link>
    <gazebo reference="right_gripper_finger1_finger_tip_link">
        <implicitSpringDamper>1</implicitSpringDamper>
        <mu1>100000</mu1>
        <mu2>100000</mu2>
        <kp>100000000.0</kp>
        <kd>1.0</kd>
    </gazebo>
    <link name="right_gripper_finger2_finger_tip_link">
        <visual>
            <geometry>
                <mesh filename="package://robotiq_85_description/meshes/visual/robotiq_85_finger_tip_link.dae" />
            </geometry>
        </visual>
        <collision>
            <geometry>
                <mesh filename="package://robotiq_85_description/meshes/collision/robotiq_85_finger_tip_link.stl" />
            </geometry>
        </collision>
        
<inertial>
            <mass value="0.019555" />
            <origin xyz="0.0 0.0 0.0" />
            <inertia ixx="0.000002" ixy="0.000000" ixz="0.000000" iyx="0.000000" iyy="0.000005" iyz="0.000000" izx="0.000000" izy="0.000000" izz="0.000006" />
        </inertial>

    </link>
    <gazebo reference="right_gripper_finger2_finger_tip_link">
        <implicitSpringDamper>1</implicitSpringDamper>
        <mu1>100000</mu1>
        <mu2>100000</mu2>
        <kp>100000000.0</kp>
        <kd>1.0</kd>
    </gazebo>
    <gazebo>
        <plugin filename="libgazebo_grasp_fix.so" name="gazebo_grasp_fix">
            <arm>
                <arm_name>gripper_arm</arm_name>
                <palm_link>right_ee_link</palm_link>
                <gripper_link>right_gripper_finger1_finger_tip_link</gripper_link>
                <gripper_link>right_gripper_finger2_finger_tip_link</gripper_link>
            </arm>
            <forces_angle_tolerance>100</forces_angle_tolerance>
            <update_rate>2</update_rate>
            <grip_count_threshold>1</grip_count_threshold>
            <max_grip_count>2</max_grip_count>
            <release_tolerance>0.005</release_tolerance>
            <disable_collisions_on_attach>true</disable_collisions_on_attach>
            <contact_topic>__default_topic__</contact_topic>
        </plugin>
    </gazebo>
    <transmission name="right_gripper_finger1_trans">
        <type>transmission_interface/SimpleTransmission</type>
        <joint name="right_gripper_finger1_joint">
            <hardwareInterface>PositionJointInterface</hardwareInterface>
        </joint>
        <actuator name="right_gripper_finger1_motor">
            <mechanicalReduction>1</mechanicalReduction>
            <hardwareInterface>PositionJointInterface</hardwareInterface>
        </actuator>
    </transmission>
    <gazebo>
        <!-- loading plugin: mimic joints works in gazebo now -->
        <plugin filename="libroboticsgroup_gazebo_mimic_joint_plugin.so" name="right_mimic_robotiq_85_1">
            <joint>right_gripper_finger1_joint</joint>
            <mimicJoint>right_gripper_finger2_joint</mimicJoint>
            <!--multiplier>1.0</multiplier>
                <offset>0.0</offset-->
        </plugin>
        <plugin filename="libroboticsgroup_gazebo_mimic_joint_plugin.so" name="right_mimic_robotiq_85_2">
            <joint>right_gripper_finger1_joint</joint>
            <mimicJoint>right_gripper_finger2_inner_knuckle_joint</mimicJoint>
            <!--multiplier>1.0</multiplier>
                <offset>0.0</offset-->
        </plugin>
        <plugin filename="libroboticsgroup_gazebo_mimic_joint_plugin.so" name="right_mimic_robotiq_85_3">
            <joint>right_gripper_finger1_joint</joint>
            <mimicJoint>right_gripper_finger1_inner_knuckle_joint</mimicJoint>
            <!--multiplier>1.0</multiplier>
                <offset>0.0</offset-->
        </plugin>
        <plugin filename="libroboticsgroup_gazebo_mimic_joint_plugin.so" name="right_mimic_robotiq_85_4">
            <joint>right_gripper_finger1_joint</joint>
            <mimicJoint>right_gripper_finger1_finger_tip_joint</mimicJoint>
            <multiplier>-1.0</multiplier>
            <offset>0.0</offset>
        </plugin>
        <plugin filename="libroboticsgroup_gazebo_mimic_joint_plugin.so" name="right_mimic_robotiq_85_5">
            <joint>right_gripper_finger1_joint</joint>
            <mimicJoint>right_gripper_finger2_finger_tip_joint</mimicJoint>
            <multiplier>-1.0</multiplier>
            <offset>0.0</offset>
        </plugin>
    </gazebo>
    <transmission name="trans_right_shoulder_pan_joint">
        <type>transmission_interface/SimpleTransmission</type>
        <joint name="right_shoulder_pan_joint">
            <hardwareInterface>hardware_interface/EffortJointInterface</hardwareInterface>
        </joint>
        <actuator name="right_shoulder_pan_joint_motor">
            <hardwareInterface>hardware_interface/EffortJointInterface</hardwareInterface>
            <mechanicalReduction>1</mechanicalReduction>
        </actuator>
    </transmission>
    <transmission name="trans_right_shoulder_lift_joint">
        <type>transmission_interface/SimpleTransmission</type>
        <joint name="right_shoulder_lift_joint">
            <hardwareInterface>hardware_interface/EffortJointInterface</hardwareInterface>
        </joint>
        <actuator name="right_shoulder_lift_joint_motor">
            <hardwareInterface>hardware_interface/EffortJointInterface</hardwareInterface>
            <mechanicalReduction>1</mechanicalReduction>
        </actuator>
    </transmission>
    <transmission name="trans_right_elbow_joint">
        <type>transmission_interface/SimpleTransmission</type>
        <joint name="right_elbow_joint">
            <hardwareInterface>hardware_interface/EffortJointInterface</hardwareInterface>
        </joint>
        <actuator name="right_elbow_joint_motor">
            <hardwareInterface>hardware_interface/EffortJointInterface</hardwareInterface>
            <mechanicalReduction>1</mechanicalReduction>
        </actuator>
    </transmission>
    <transmission name="trans_right_wrist_1_joint">
        <type>transmission_interface/SimpleTransmission</type>
        <joint name="right_wrist_1_joint">
            <hardwareInterface>hardware_interface/EffortJointInterface</hardwareInterface>
        </joint>
        <actuator name="right_wrist_1_joint_motor">
            <hardwareInterface>hardware_interface/EffortJointInterface</hardwareInterface>
            <mechanicalReduction>1</mechanicalReduction>
        </actuator>
    </transmission>
    <transmission name="trans_right_wrist_2_joint">
        <type>transmission_interface/SimpleTransmission</type>
        <joint name="right_wrist_2_joint">
            <hardwareInterface>hardware_interface/EffortJointInterface</hardwareInterface>
        </joint>
        <actuator name="right_wrist_2_joint_motor">
            <hardwareInterface>hardware_interface/EffortJointInterface</hardwareInterface>
            <mechanicalReduction>1</mechanicalReduction>
        </actuator>
    </transmission>
    <transmission name="trans_right_wrist_3_joint">
        <type>transmission_interface/SimpleTransmission</type>
        <joint name="right_wrist_3_joint">
            <hardwareInterface>hardware_interface/EffortJointInterface</hardwareInterface>
        </joint>
        <actuator name="right_wrist_3_joint_motor">
            <hardwareInterface>hardware_interface/EffortJointInterface</hardwareInterface>
            <mechanicalReduction>1</mechanicalReduction>
        </actuator>
    </transmission>
    <transmission name="trans_right_gripper_finger1_joint">
        <type>transmission_interface/SimpleTransmission</type>
        <joint name="right_gripper_finger1_joint">
            <hardwareInterface>hardware_interface/EffortJointInterface</hardwareInterface>
        </joint>
        <actuator name="right_gripper_finger1_joint_motor">
            <hardwareInterface>hardware_interface/EffortJointInterface</hardwareInterface>
            <mechanicalReduction>1</mechanicalReduction>
        </actuator>
    </transmission>
    <transmission name="trans_right_gripper_finger2_joint">
        <type>transmission_interface/SimpleTransmission</type>
        <joint name="right_gripper_finger2_joint">
            <hardwareInterface>hardware_interface/EffortJointInterface</hardwareInterface>
        </joint>
        <actuator name="right_gripper_finger2_joint_motor">
            <hardwareInterface>hardware_interface/EffortJointInterface</hardwareInterface>
            <mechanicalReduction>1</mechanicalReduction>
        </actuator>
    </transmission>
    <transmission name="trans_right_gripper_finger1_inner_knuckle_joint">
        <type>transmission_interface/SimpleTransmission</type>
        <joint name="right_gripper_finger1_inner_knuckle_joint">
            <hardwareInterface>hardware_interface/EffortJointInterface</hardwareInterface>
        </joint>
        <actuator name="right_gripper_finger1_inner_knuckle_joint_motor">
            <hardwareInterface>hardware_interface/EffortJointInterface</hardwareInterface>
            <mechanicalReduction>1</mechanicalReduction>
        </actuator>
    </transmission>
    <transmission name="trans_right_gripper_finger2_inner_knuckle_joint">
        <type>transmission_interface/SimpleTransmission</type>
        <joint name="right_gripper_finger2_inner_knuckle_joint">
            <hardwareInterface>hardware_interface/EffortJointInterface</hardwareInterface>
        </joint>
        <actuator name="right_gripper_finger2_inner_knuckle_joint_motor">
            <hardwareInterface>hardware_interface/EffortJointInterface</hardwareInterface>
            <mechanicalReduction>1</mechanicalReduction>
        </actuator>
    </transmission>
    <transmission name="trans_right_gripper_finger1_finger_tip_joint">
        <type>transmission_interface/SimpleTransmission</type>
        <joint name="right_gripper_finger1_finger_tip_joint">
            <hardwareInterface>hardware_interface/EffortJointInterface</hardwareInterface>
        </joint>
        <actuator name="right_gripper_finger1_finger_tip_joint_motor">
            <hardwareInterface>hardware_interface/EffortJointInterface</hardwareInterface>
            <mechanicalReduction>1</mechanicalReduction>
        </actuator>
    </transmission>
    <transmission name="trans_right_gripper_finger2_finger_tip_joint">
        <type>transmission_interface/SimpleTransmission</type>
        <joint name="right_gripper_finger2_finger_tip_joint">
            <hardwareInterface>hardware_interface/EffortJointInterface</hardwareInterface>
        </joint>
        <actuator name="right_gripper_finger2_finger_tip_joint_motor">
            <hardwareInterface>hardware_interface/EffortJointInterface</hardwareInterface>
            <mechanicalReduction>1</mechanicalReduction>
        </actuator>
    </transmission>
    <gazebo>
        <plugin name="gazebo_ros_control" filename="libgazebo_ros_control.so">
            <robotNamespace>/</robotNamespace>
        </plugin>
    </gazebo>
</robot>

<transmission name="right_shoulder_pan_trans">
        <type>transmission_interface/SimpleTransmission</type>
        <joint name="right_shoulder_pan_joint">
            <hardwareInterface>hardware_interface/PositionJointInterface</hardwareInterface>
        </joint>
        <actuator name="right_shoulder_pan_motor">
            <mechanicalReduction>1</mechanicalReduction>
        </actuator>
    </transmission>
    <transmission name="right_shoulder_lift_trans">
        <type>transmission_interface/SimpleTransmission</type>
        <joint name="right_shoulder_lift_joint">
            <hardwareInterface>hardware_interface/PositionJointInterface</hardwareInterface>
        </joint>
        <actuator name="right_shoulder_lift_motor">
            <mechanicalReduction>1</mechanicalReduction>
        </actuator>
    </transmission>
    <transmission name="right_elbow_trans">
        <type>transmission_interface/SimpleTransmission</type>
        <joint name="right_elbow_joint">
            <hardwareInterface>hardware_interface/PositionJointInterface</hardwareInterface>
        </joint>
        <actuator name="right_elbow_motor">
            <mechanicalReduction>1</mechanicalReduction>
        </actuator>
    </transmission>
    <transmission name="right_wrist_1_trans">
        <type>transmission_interface/SimpleTransmission</type>
        <joint name="right_wrist_1_joint">
            <hardwareInterface>hardware_interface/PositionJointInterface</hardwareInterface>
        </joint>
        <actuator name="right_wrist_1_motor">
            <mechanicalReduction>1</mechanicalReduction>
        </actuator>
    </transmission>
    <transmission name="right_wrist_2_trans">
        <type>transmission_interface/SimpleTransmission</type>
        <joint name="right_wrist_2_joint">
            <hardwareInterface>hardware_interface/PositionJointInterface</hardwareInterface>
        </joint>
        <actuator name="right_wrist_2_motor">
            <mechanicalReduction>1</mechanicalReduction>
        </actuator>
    </transmission>
    <transmission name="right_wrist_3_trans">
        <type>transmission_interface/SimpleTransmission</type>
        <joint name="right_wrist_3_joint">
            <hardwareInterface>hardware_interface/PositionJointInterface</hardwareInterface>
        </joint>
        <actuator name="right_wrist_3_motor">
            <mechanicalReduction>1</mechanicalReduction>
        </actuator>
    </transmission>
    <gazebo reference="right_shoulder_link">
        <selfCollide>true</selfCollide>
    </gazebo>
    <gazebo reference="right_upper_arm_link">
        <selfCollide>true</selfCollide>
    </gazebo>
    <gazebo reference="right_forearm_link">
        <selfCollide>true</selfCollide>
    </gazebo>
    <gazebo reference="right_wrist_1_link">
        <selfCollide>true</selfCollide>
    </gazebo>
    <gazebo reference="right_wrist_3_link">
        <selfCollide>true</selfCollide>
    </gazebo>
    <gazebo reference="right_wrist_2_link">
        <selfCollide>true</selfCollide>
    </gazebo>
    <gazebo reference="right_ee_link">
        <selfCollide>true</selfCollide>
    </gazebo>
    <!-- ROS base_link to UR 'Base' Coordinates transform -->
    <link name="right_base" />
    <joint name="right_base_link-base_fixed_joint" type="fixed">
        <!-- NOTE: this rotation is only needed as long as base_link itself is
                 not corrected wrt the real robot (ie: rotated over 180
                 degrees)
      -->
        <origin rpy="0 0 -3.14159265359" xyz="0 0 0" />
        <parent link="right_base_link" />
        <child link="right_base" />
    </joint>
    <!-- Frame coincident with all-zeros TCP on UR controller -->
    <link name="right_tool0" />
    <joint name="right_wrist_3_link-tool0_fixed_joint" type="fixed">
        <origin rpy="-1.57079632679 0 0" xyz="0 0.0823 0" />
        <parent link="right_wrist_3_link" />
        <child link="right_tool0" />
    </joint>
    <link name="world" />
    <link name="ur5_frame">
        <visual>
            <origin rpy="0.0 0 0" xyz="0 0 0" />
            <geometry>
                <mesh filename="package://daurar_description/meshes/Dual_Arm_UR5Frame.STL" />
            </geometry>
        </visual>
        <collision>
            <origin rpy="0.0 0 0" xyz="0 0 0" />
            <geometry>
                <mesh filename="package://daurar_description/meshes/Dual_Arm_UR5Frame.STL" />
            </geometry>
        </collision>
        <inertial>
            <origin rpy="0.0 0 0" xyz="0 0 0" />
            <mass value="27.2155" />
            <inertia ixx="5.01" ixy="0.0" ixz="0.0" iyy="5.07" iyz="0.0" izz="3.20" />
        </inertial>
    </link>
    <joint name="ur5_frame_to_world" type="fixed">
        <parent link="world" />
        <child link="ur5_frame" />
        <origin rpy="0.0 0.0 0.0" xyz="0.0 0.0 0.0" />
    </joint>
    <!-- right arm -->
    <joint name="world_joint_2" type="fixed">
        <parent link="ur5_frame" />
        <child link="right_base_link" />
        <origin rpy="-0.785398163397 3.14159265359  1.57079632679" xyz="0.265 0.635 1.275" />
    </joint>
    <link name="right_gripper_base_link">
        <visual>
            <geometry>
                <mesh filename="package://robotiq_85_description/meshes/visual/robotiq_85_base_link.dae" />
            </geometry>
        </visual>
        <collision>
            <geometry>
                <mesh filename="package://robotiq_85_description/meshes/collision/robotiq_85_base_link.stl" />
            </geometry>
        </collision>
        <inertial>
            <mass value="0.636951" />
            <origin xyz="0.0 0.0 0.0" />
            <inertia ixx="0.000380" ixy="0.000000" ixz="0.000000" iyx="0.000000" iyy="0.001110" iyz="0.000000" izx="0.000000" izy="0.000000" izz="0.001171" />
        </inertial>
    </link>
    <joint name="right_gripper_base_joint" type="fixed">
        <parent link="right_ee_link" />
        <child link="right_gripper_base_link" />
        <origin rpy="0 0 0" xyz="0 0 0" />
    </joint>
    <gazebo reference="right_gripper_base_link">
        <implicitSpringDamper>1</implicitSpringDamper>
        <mu1>100000</mu1>
        <mu2>100000</mu2>
        <kp>100000000.0</kp>
        <kd>1.0</kd>
    </gazebo>
    <joint name="right_gripper_finger1_joint" type="revolute">
        <parent link="right_gripper_base_link" />
        <child link="right_gripper_finger1_knuckle_link" />
        <axis xyz="0 0 1" />
        <origin rpy="3.14159265359 0.0 0.0" xyz="0.05490451627 0.03060114443 0.0" />
        <limit effort="1000" lower="0.0" upper="0.804" velocity="2.0" />
    </joint>
    <joint name="right_gripper_finger2_joint" type="revolute">
        <parent link="right_gripper_base_link" />
        <child link="right_gripper_finger2_knuckle_link" />
        <axis xyz="0 0 1" />
        <origin rpy="0.0 0.0 0.0" xyz="0.05490451627 -0.03060114443 0.0" />
        <limit effort="1000" lower="-3.14" upper="3.14" velocity="100.0" />
        <mimic joint="right_gripper_finger1_joint" />
    </joint>
    <link name="right_gripper_finger1_knuckle_link">
        <visual>
            <geometry>
                <mesh filename="package://robotiq_85_description/meshes/visual/robotiq_85_knuckle_link.dae" />
            </geometry>
        </visual>
        <collision>
            <geometry>
                <mesh filename="package://robotiq_85_description/meshes/collision/robotiq_85_knuckle_link.stl" />
            </geometry>
        </collision>
        <inertial>
            <mass value="0.018491" />
            <origin xyz="0.0 0.0 0.0" />
            <inertia ixx="0.000009" ixy="-0.000001" ixz="0.000000" iyx="-0.000001" iyy="0.000001" iyz="0.000000" izx="0.000000" izy="0.000000" izz="0.000010" />
        </inertial>
    </link>
    <gazebo reference="right_gripper_finger1_knuckle_link">
        <implicitSpringDamper>1</implicitSpringDamper>
        <mu1>100000</mu1>
        <mu2>100000</mu2>
        <kp>100000000.0</kp>
        <kd>1.0</kd>
    </gazebo>
    <link name="right_gripper_finger2_knuckle_link">
        <visual>
            <geometry>
                <mesh filename="package://robotiq_85_description/meshes/visual/robotiq_85_knuckle_link.dae" />
            </geometry>
        </visual>
        <collision>
            <geometry>
                <mesh filename="package://robotiq_85_description/meshes/collision/robotiq_85_knuckle_link.stl" />
            </geometry>
        </collision>
        <inertial>
            <mass value="0.018491" />
            <origin xyz="0.0 0.0 0.0" />
            <inertia ixx="0.000009" ixy="-0.000001" ixz="0.000000" iyx="-0.000001" iyy="0.000001" iyz="0.000000" izx="0.000000" izy="0.000000" izz="0.000010" />
        </inertial>
    </link>
    <gazebo reference="right_gripper_finger2_knuckle_link">
        <implicitSpringDamper>1</implicitSpringDamper>
        <mu1>100000</mu1>
        <mu2>100000</mu2>
        <kp>100000000.0</kp>
        <kd>1.0</kd>
    </gazebo>
    <joint name="right_gripper_finger1_finger_joint" type="fixed">
        <parent link="right_gripper_finger1_knuckle_link" />
        <child link="right_gripper_finger1_finger_link" />
        <origin rpy="0 0 0" xyz="-0.00408552455 -0.03148604435 0.0" />
    </joint>
    <joint name="right_gripper_finger2_finger_joint" type="fixed">
        <parent link="right_gripper_finger2_knuckle_link" />
        <child link="right_gripper_finger2_finger_link" />
        <origin rpy="0 0 0" xyz="-0.00408552455 -0.03148604435 0.0" />
    </joint>
    <link name="right_gripper_finger1_finger_link">
        <visual>
            <geometry>
                <mesh filename="package://robotiq_85_description/meshes/visual/robotiq_85_finger_link.dae" />
            </geometry>
        </visual>
        <collision>
            <geometry>
                <mesh filename="package://robotiq_85_description/meshes/collision/robotiq_85_finger_link.stl" />
            </geometry>
        </collision>
        <inertial>
            <mass value="0.027309" />
            <origin xyz="0.0 0.0 0.0" />
            <inertia ixx="0.000003" ixy="-0.000002" ixz="0.000000" iyx="-0.000002" iyy="0.000021" iyz="0.000000" izx="0.000000" izy="0.000000" izz="0.000020" />
        </inertial>
    </link>
    <gazebo reference="right_gripper_finger1_finger_link">
        <implicitSpringDamper>1</implicitSpringDamper>
        <mu1>100000</mu1>
        <mu2>100000</mu2>
        <kp>100000000.0</kp>
        <kd>1.0</kd>
    </gazebo>
    <link name="right_gripper_finger2_finger_link">
        <visual>
            <geometry>
                <mesh filename="package://robotiq_85_description/meshes/visual/robotiq_85_finger_link.dae" />
            </geometry>
        </visual>
        <collision>
            <geometry>
                <mesh filename="package://robotiq_85_description/meshes/collision/robotiq_85_finger_link.stl" />
            </geometry>
        </collision>
        <inertial>
            <mass value="0.027309" />
            <origin xyz="0.0 0.0 0.0" />
            <inertia ixx="0.000003" ixy="-0.000002" ixz="0.000000" iyx="-0.000002" iyy="0.000021" iyz="0.000000" izx="0.000000" izy="0.000000" izz="0.000020" />
        </inertial>
    </link>
    <gazebo reference="right_gripper_finger2_finger_link">
        <implicitSpringDamper>1</implicitSpringDamper>
        <mu1>100000</mu1>
        <mu2>100000</mu2>
        <kp>100000000.0</kp>
        <kd>1.0</kd>
    </gazebo>
    <joint name="right_gripper_finger1_inner_knuckle_joint" type="continuous">
        <parent link="right_gripper_base_link" />
        <child link="right_gripper_finger1_inner_knuckle_link" />
        <axis xyz="0 0 1" />
        <origin rpy="3.14159265359 0.0 0.0" xyz="0.06142 0.0127 0" />
        <limit effort="0.1" lower="-3.14" upper="3.14" velocity="100.0" />
        <mimic joint="right_gripper_finger1_joint" offset="0" />
    </joint>
    <joint name="right_gripper_finger2_inner_knuckle_joint" type="continuous">
        <parent link="right_gripper_base_link" />
        <child link="right_gripper_finger2_inner_knuckle_link" />
        <axis xyz="0 0 1" />
        <origin rpy="0 0 0" xyz="0.06142 -0.0127 0" />
        <limit effort="0.1" lower="-3.14" upper="3.14" velocity="100.0" />
        <mimic joint="right_gripper_finger1_joint" offset="0" />
    </joint>
    <link name="right_gripper_finger1_inner_knuckle_link">
        <visual>
            <geometry>
                <mesh filename="package://robotiq_85_description/meshes/visual/robotiq_85_inner_knuckle_link.dae" />
            </geometry>
        </visual>
        <collision>
            <geometry>
                <mesh filename="package://robotiq_85_description/meshes/collision/robotiq_85_inner_knuckle_link.stl" />
            </geometry>
        </collision>
        <inertial>
            <mass value="0.029951" />
            <origin xyz="0.0 0.0 0.0" />
            <inertia ixx="0.000039" ixy="0.000000" ixz="0.000000" iyx="0.000000" iyy="0.000005" iyz="0.000000" izx="0.000000" izy="0.000000" izz="0.000035" />
        </inertial>
    </link>
    <gazebo reference="right_gripper_finger1_inner_knuckle_link">
        <implicitSpringDamper>1</implicitSpringDamper>
        <mu1>100000</mu1>
        <mu2>100000</mu2>
        <kp>100000000.0</kp>
        <kd>1.0</kd>
    </gazebo>
    <link name="right_gripper_finger2_inner_knuckle_link">
        <visual>
            <geometry>
                <mesh filename="package://robotiq_85_description/meshes/visual/robotiq_85_inner_knuckle_link.dae" />
            </geometry>
        </visual>
        <collision>
            <geometry>
                <mesh filename="package://robotiq_85_description/meshes/collision/robotiq_85_inner_knuckle_link.stl" />
            </geometry>
        </collision>
        <inertial>
            <mass value="0.029951" />
            <origin xyz="0.0 0.0 0.0" />
            <inertia ixx="0.000039" ixy="0.000000" ixz="0.000000" iyx="0.000000" iyy="0.000005" iyz="0.000000" izx="0.000000" izy="0.000000" izz="0.000035" />
        </inertial>
    </link>
    <gazebo reference="right_gripper_finger2_inner_knuckle_link">
        <implicitSpringDamper>1</implicitSpringDamper>
        <mu1>100000</mu1>
        <mu2>100000</mu2>
        <kp>100000000.0</kp>
        <kd>1.0</kd>
    </gazebo>
    <joint name="right_gripper_finger1_finger_tip_joint" type="continuous">
        <parent link="right_gripper_finger1_inner_knuckle_link" />
        <child link="right_gripper_finger1_finger_tip_link" />
        <axis xyz="0 0 1" />
        <origin rpy="0.0 0.0 0.0" xyz="0.04303959807 -0.03759940821 0.0" />
        <limit effort="0.1" lower="-3.14" upper="3.14" velocity="100.0" />
        <mimic joint="right_gripper_finger1_joint" multiplier="-1" />
    </joint>
    <joint name="right_gripper_finger2_finger_tip_joint" type="continuous">
        <parent link="right_gripper_finger2_inner_knuckle_link" />
        <child link="right_gripper_finger2_finger_tip_link" />
        <axis xyz="0 0 1" />
        <origin rpy="0.0 0.0 0.0" xyz="0.04303959807 -0.03759940821  0.0" />
        <limit effort="0.1" lower="-3.14" upper="3.14" velocity="100.0" />
        <mimic joint="right_gripper_finger1_joint" multiplier="-1" />
    </joint>
    <link name="right_gripper_finger1_finger_tip_link">
        <visual>
            <geometry>
                <mesh filename="package://robotiq_85_description/meshes/visual/robotiq_85_finger_tip_link.dae" />
            </geometry>
        </visual>
        <collision>
            <geometry>
                <mesh filename="package://robotiq_85_description/meshes/collision/robotiq_85_finger_tip_link.stl" />
            </geometry>
        </collision>
        <inertial>
            <mass value="0.019555" />
            <origin xyz="0.0 0.0 0.0" />
            <inertia ixx="0.000002" ixy="0.000000" ixz="0.000000" iyx="0.000000" iyy="0.000005" iyz="0.000000" izx="0.000000" izy="0.000000" izz="0.000006" />
        </inertial>
    </link>
    <gazebo reference="right_gripper_finger1_finger_tip_link">
        <implicitSpringDamper>1</implicitSpringDamper>
        <mu1>100000</mu1>
        <mu2>100000</mu2>
        <kp>100000000.0</kp>
        <kd>1.0</kd>
    </gazebo>
    <link name="right_gripper_finger2_finger_tip_link">
        <visual>
            <geometry>
                <mesh filename="package://robotiq_85_description/meshes/visual/robotiq_85_finger_tip_link.dae" />
            </geometry>
        </visual>
        <collision>
            <geometry>
                <mesh filename="package://robotiq_85_description/meshes/collision/robotiq_85_finger_tip_link.stl" />
            </geometry>
        </collision>
        <inertial>
            <mass value="0.019555" />
            <origin xyz="0.0 0.0 0.0" />
            <inertia ixx="0.000002" ixy="0.000000" ixz="0.000000" iyx="0.000000" iyy="0.000005" iyz="0.000000" izx="0.000000" izy="0.000000" izz="0.000006" />
        </inertial>
    </link>
    <gazebo reference="right_gripper_finger2_finger_tip_link">
        <implicitSpringDamper>1</implicitSpringDamper>
        <mu1>100000</mu1>
        <mu2>100000</mu2>
        <kp>100000000.0</kp>
        <kd>1.0</kd>
    </gazebo>
    <gazebo>
        <plugin filename="libgazebo_grasp_fix.so" name="gazebo_grasp_fix">
            <arm>
                <arm_name>gripper_arm</arm_name>
                <palm_link>right_ee_link</palm_link>
                <gripper_link>right_gripper_finger1_finger_tip_link</gripper_link>
                <gripper_link>right_gripper_finger2_finger_tip_link</gripper_link>
            </arm>
            <forces_angle_tolerance>100</forces_angle_tolerance>
            <update_rate>2</update_rate>
            <grip_count_threshold>1</grip_count_threshold>
            <max_grip_count>2</max_grip_count>
            <release_tolerance>0.005</release_tolerance>
            <disable_collisions_on_attach>true</disable_collisions_on_attach>
            <contact_topic>__default_topic__</contact_topic>
        </plugin>
    </gazebo>
    <transmission name="right_gripper_finger1_trans">
        <type>transmission_interface/SimpleTransmission</type>
        <joint name="right_gripper_finger1_joint">
            <hardwareInterface>PositionJointInterface</hardwareInterface>
        </joint>
        <actuator name="right_gripper_finger1_motor">
            <mechanicalReduction>1</mechanicalReduction>
            <hardwareInterface>PositionJointInterface</hardwareInterface>
        </actuator>
    </transmission>
    <gazebo>
        <!-- loading plugin: mimic joints works in gazebo now -->
        <plugin filename="libroboticsgroup_gazebo_mimic_joint_plugin.so" name="right_mimic_robotiq_85_1">
            <joint>right_gripper_finger1_joint</joint>
            <mimicJoint>right_gripper_finger2_joint</mimicJoint>
            <!--multiplier>1.0</multiplier>
                <offset>0.0</offset-->
        </plugin>
        <plugin filename="libroboticsgroup_gazebo_mimic_joint_plugin.so" name="right_mimic_robotiq_85_2">
            <joint>right_gripper_finger1_joint</joint>
            <mimicJoint>right_gripper_finger2_inner_knuckle_joint</mimicJoint>
            <!--multiplier>1.0</multiplier>
                <offset>0.0</offset-->
        </plugin>
        <plugin filename="libroboticsgroup_gazebo_mimic_joint_plugin.so" name="right_mimic_robotiq_85_3">
            <joint>right_gripper_finger1_joint</joint>
            <mimicJoint>right_gripper_finger1_inner_knuckle_joint</mimicJoint>
            <!--multiplier>1.0</multiplier>
                <offset>0.0</offset-->
        </plugin>
        <plugin filename="libroboticsgroup_gazebo_mimic_joint_plugin.so" name="right_mimic_robotiq_85_4">
            <joint>right_gripper_finger1_joint</joint>
            <mimicJoint>right_gripper_finger1_finger_tip_joint</mimicJoint>
            <multiplier>-1.0</multiplier>
            <offset>0.0</offset>
        </plugin>
        <plugin filename="libroboticsgroup_gazebo_mimic_joint_plugin.so" name="right_mimic_robotiq_85_5">
            <joint>right_gripper_finger1_joint</joint>
            <mimicJoint>right_gripper_finger2_finger_tip_joint</mimicJoint>
            <multiplier>-1.0</multiplier>
            <offset>0.0</offset>
        </plugin>
    </gazebo>
    <transmission name="trans_right_shoulder_pan_joint">
        <type>transmission_interface/SimpleTransmission</type>
        <joint name="right_shoulder_pan_joint">
            <hardwareInterface>hardware_interface/EffortJointInterface</hardwareInterface>
        </joint>
        <actuator name="right_shoulder_pan_joint_motor">
            <hardwareInterface>hardware_interface/EffortJointInterface</hardwareInterface>
            <mechanicalReduction>1</mechanicalReduction>
        </actuator>
    </transmission>
    <transmission name="trans_right_shoulder_lift_joint">
        <type>transmission_interface/SimpleTransmission</type>
        <joint name="right_shoulder_lift_joint">
            <hardwareInterface>hardware_interface/EffortJointInterface</hardwareInterface>
        </joint>
        <actuator name="right_shoulder_lift_joint_motor">
            <hardwareInterface>hardware_interface/EffortJointInterface</hardwareInterface>
            <mechanicalReduction>1</mechanicalReduction>
        </actuator>
    </transmission>
    <transmission name="trans_right_elbow_joint">
        <type>transmission_interface/SimpleTransmission</type>
        <joint name="right_elbow_joint">
            <hardwareInterface>hardware_interface/EffortJointInterface</hardwareInterface>
        </joint>
        <actuator name="right_elbow_joint_motor">
            <hardwareInterface>hardware_interface/EffortJointInterface</hardwareInterface>
            <mechanicalReduction>1</mechanicalReduction>
        </actuator>
    </transmission>
    <transmission name="trans_right_wrist_1_joint">
        <type>transmission_interface/SimpleTransmission</type>
        <joint name="right_wrist_1_joint">
            <hardwareInterface>hardware_interface/EffortJointInterface</hardwareInterface>
        </joint>
        <actuator name="right_wrist_1_joint_motor">
            <hardwareInterface>hardware_interface/EffortJointInterface</hardwareInterface>
            <mechanicalReduction>1</mechanicalReduction>
        </actuator>
    </transmission>
    <transmission name="trans_right_wrist_2_joint">
        <type>transmission_interface/SimpleTransmission</type>
        <joint name="right_wrist_2_joint">
            <hardwareInterface>hardware_interface/EffortJointInterface</hardwareInterface>
        </joint>
        <actuator name="right_wrist_2_joint_motor">
            <hardwareInterface>hardware_interface/EffortJointInterface</hardwareInterface>
            <mechanicalReduction>1</mechanicalReduction>
        </actuator>
    </transmission>
    <transmission name="trans_right_wrist_3_joint">
        <type>transmission_interface/SimpleTransmission</type>
        <joint name="right_wrist_3_joint">
            <hardwareInterface>hardware_interface/EffortJointInterface</hardwareInterface>
        </joint>
        <actuator name="right_wrist_3_joint_motor">
            <hardwareInterface>hardware_interface/EffortJointInterface</hardwareInterface>
            <mechanicalReduction>1</mechanicalReduction>
        </actuator>
    </transmission>
    <transmission name="trans_right_gripper_finger1_joint">
        <type>transmission_interface/SimpleTransmission</type>
        <joint name="right_gripper_finger1_joint">
            <hardwareInterface>hardware_interface/EffortJointInterface</hardwareInterface>
        </joint>
        <actuator name="right_gripper_finger1_joint_motor">
            <hardwareInterface>hardware_interface/EffortJointInterface</hardwareInterface>
            <mechanicalReduction>1</mechanicalReduction>
        </actuator>
    </transmission>
    <transmission name="trans_right_gripper_finger2_joint">
        <type>transmission_interface/SimpleTransmission</type>
        <joint name="right_gripper_finger2_joint">
            <hardwareInterface>hardware_interface/EffortJointInterface</hardwareInterface>
        </joint>
        <actuator name="right_gripper_finger2_joint_motor">
            <hardwareInterface>hardware_interface/EffortJointInterface</hardwareInterface>
            <mechanicalReduction>1</mechanicalReduction>
        </actuator>
    </transmission>
    <transmission name="trans_right_gripper_finger1_inner_knuckle_joint">
        <type>transmission_interface/SimpleTransmission</type>
        <joint name="right_gripper_finger1_inner_knuckle_joint">
            <hardwareInterface>hardware_interface/EffortJointInterface</hardwareInterface>
        </joint>
        <actuator name="right_gripper_finger1_inner_knuckle_joint_motor">
            <hardwareInterface>hardware_interface/EffortJointInterface</hardwareInterface>
            <mechanicalReduction>1</mechanicalReduction>
        </actuator>
    </transmission>
    <transmission name="trans_right_gripper_finger2_inner_knuckle_joint">
        <type>transmission_interface/SimpleTransmission</type>
        <joint name="right_gripper_finger2_inner_knuckle_joint">
            <hardwareInterface>hardware_interface/EffortJointInterface</hardwareInterface>
        </joint>
        <actuator name="right_gripper_finger2_inner_knuckle_joint_motor">
            <hardwareInterface>hardware_interface/EffortJointInterface</hardwareInterface>
            <mechanicalReduction>1</mechanicalReduction>
        </actuator>
    </transmission>
    <transmission name="trans_right_gripper_finger1_finger_tip_joint">
        <type>transmission_interface/SimpleTransmission</type>
        <joint name="right_gripper_finger1_finger_tip_joint">
            <hardwareInterface>hardware_interface/EffortJointInterface</hardwareInterface>
        </joint>
        <actuator name="right_gripper_finger1_finger_tip_joint_motor">
            <hardwareInterface>hardware_interface/EffortJointInterface</hardwareInterface>
            <mechanicalReduction>1</mechanicalReduction>
        </actuator>
    </transmission>
    <transmission name="trans_right_gripper_finger2_finger_tip_joint">
        <type>transmission_interface/SimpleTransmission</type>
        <joint name="right_gripper_finger2_finger_tip_joint">
            <hardwareInterface>hardware_interface/EffortJointInterface</hardwareInterface>
        </joint>
        <actuator name="right_gripper_finger2_finger_tip_joint_motor">
            <hardwareInterface>hardware_interface/EffortJointInterface</hardwareInterface>
            <mechanicalReduction>1</mechanicalReduction>
        </actuator>
    </transmission>
    <gazebo>
        <plugin name="gazebo_ros_control" filename="libgazebo_ros_control.so">
            <robotNamespace>/</robotNamespace>
        </plugin>
    </gazebo>
</robot>
<?xml version="1.0" ?>
<robot name="ur5" xmlns:xacro="http://ros.org/wiki/xacro">
    <gazebo>
        <plugin filename="libgazebo_ros_control.so" name="ros_control">
            <!--robotNamespace>/</robotNamespace-->
            <!--robotSimType>gazebo_ros_control/DefaultRobotHWSim</robotSimType-->
        </plugin>
    </gazebo>
    <link name="right_base_link">
        <visual>
            <origin rpy="0 0 3.14159265359" xyz="0 0 0" />
            <geometry>
                <mesh filename="package://ur_description/meshes/ur5/visual/base.dae" />
            </geometry>
            <material name="LightGrey">
                <color rgba="0.7 0.7 0.7 1.0" />
            </material>
        </visual>
        <collision>
            <origin rpy="0 0 3.14159265359" xyz="0 0 0" />
            <geometry>
                <mesh filename="package://ur_description/meshes/ur5/collision/base.stl" />
            </geometry>
        </collision>
        
<inertial>
            <mass value="4.0" />
            <origin rpy="0 0 0" xyz="0.0 0.0 0.0" />
            <inertia ixx="0.00443333156" ixy="0.0" ixz="0.0" iyy="0.00443333156" iyz="0.0" izz="0.0072" />
        </inertial>

    </link>
    <joint name="right_shoulder_pan_joint" type="revolute">
        <parent link="right_base_link" />
        <child link="right_shoulder_link" />
        <origin rpy="0 0 3.14159265359" xyz="0 0 0.089159" />
        <axis xyz="0 0 1" />
        <limit effort="150.0" lower="-3.14159265359" upper="3.14159265359" velocity="3.15" />
        <dynamics damping="0.0" friction="0.0" />
    </joint>
    <link name="right_shoulder_link">
        <visual>
            <origin rpy="0 0 3.14159265359" xyz="0 0 0" />
            <geometry>
                <mesh filename="package://ur_description/meshes/ur5/visual/shoulder.dae" />
            </geometry>
            <material name="LightGrey">
                <color rgba="0.7 0.7 0.7 1.0" />
            </material>
        </visual>
        <collision>
            <origin rpy="0 0 3.14159265359" xyz="0 0 0" />
            <geometry>
                <mesh filename="package://ur_description/meshes/ur5/collision/shoulder.stl" />
            </geometry>
        </collision>
        
<inertial>
            <mass value="3.7" />
            <origin rpy="0 0 0" xyz="0.0 0.0 0.0" />
            <inertia ixx="0.0149723523444" ixy="0.0" ixz="0.0" iyy="0.0149723523444" iyz="0.0" izz="0.01040625" />
        </inertial>

    </link>
    <joint name="right_shoulder_lift_joint" type="revolute">
        <parent link="right_shoulder_link" />
        <child link="right_upper_arm_link" />
        <origin rpy="1.57079632679 0 0" xyz="0 0 0" />
        <axis xyz="0 0 1" />
        <limit effort="150.0" lower="-3.14159265359" upper="3.14159265359" velocity="3.15" />
        <dynamics damping="0.0" friction="0.0" />
    </joint>
    <link name="right_upper_arm_link">
        <visual>
            <origin rpy="1.57079632679 0 -1.57079632679" xyz="0 0 0.136" />
            <geometry>
                <mesh filename="package://ur_description/meshes/ur5/visual/upperarm.dae" />
            </geometry>
            <material name="LightGrey">
                <color rgba="0.7 0.7 0.7 1.0" />
            </material>
        </visual>
        <collision>
            <origin rpy="1.57079632679 0 -1.57079632679" xyz="0 0 0.136" />
            <geometry>
                <mesh filename="package://ur_description/meshes/ur5/collision/upperarm.stl" />
            </geometry>
        </collision>
        
<inertial>
            <mass value="8.393" />
            <origin rpy="0 1.57079632679 0" xyz="-0.2125 0.0 0.136" />
            <inertia ixx="0.133885781862" ixy="0.0" ixz="0.0" iyy="0.133885781862" iyz="0.0" izz="0.0151074" />
        </inertial>

    </link>
    <joint name="right_elbow_joint" type="revolute">
        <parent link="right_upper_arm_link" />
        <child link="right_forearm_link" />
        <origin rpy="0.0 0.0 0.0" xyz="-0.425 0 0" />
        <axis xyz="0 0 1" />
        <limit effort="150.0" lower="-3.14159265359" upper="3.14159265359" velocity="3.15" />
        <dynamics damping="0.0" friction="0.0" />
    </joint>
    <link name="right_forearm_link">
        <visual>
            <origin rpy="1.57079632679 0 -1.57079632679" xyz="0 0 0.0165" />
            <geometry>
                <mesh filename="package://ur_description/meshes/ur5/visual/forearm.dae" />
            </geometry>
            <material name="LightGrey">
                <color rgba="0.7 0.7 0.7 1.0" />
            </material>
        </visual>
        <collision>
            <origin rpy="1.57079632679 0 -1.57079632679" xyz="0 0 0.0165" />
            <geometry>
                <mesh filename="package://ur_description/meshes/ur5/collision/forearm.stl" />
            </geometry>
        </collision>
        
<inertial>
            <mass value="2.275" />
            <origin rpy="0 1.57079632679 0" xyz="-0.2125 0.0 0.136" />
            <inertia ixx="0.0312167910289" ixy="0.0" ixz="0.0" iyy="0.0312167910289" iyz="0.0" izz="0.004095" />
        </inertial>

    </link>
    <joint name="right_wrist_1_joint" type="revolute">
        <parent link="right_forearm_link" />
        <child link="right_wrist_1_link" />
        <origin rpy="0 0 0" xyz="-0.39225 0 0.10915" />
        <axis xyz="0 0 1" />
        <limit effort="28.0" lower="-3.14159265359" upper="3.14159265359" velocity="3.2" />
        <dynamics damping="0.0" friction="0.0" />
    </joint>
    <link name="right_wrist_1_link">
        <visual>
            <origin rpy="1.57079632679 0 0" xyz="0 0 -0.093" />
            <geometry>
                <mesh filename="package://ur_description/meshes/ur5/visual/wrist1.dae" />
            </geometry>
            <material name="LightGrey">
                <color rgba="0.7 0.7 0.7 1.0" />
            </material>
        </visual>
        <collision>
            <origin rpy="1.57079632679 0 0" xyz="0 0 -0.093" />
            <geometry>
                <mesh filename="package://ur_description/meshes/ur5/collision/wrist1.stl" />
            </geometry>
        </collision>
        
<inertial>
            <mass value="1.219" />
            <origin rpy="0 0 0" xyz="0.0 0.0 0.0" />
            <inertia ixx="0.00262426443592" ixy="0.0" ixz="0.0" iyy="0.00262426443592" iyz="0.0" izz="0.0034284375" />
        </inertial>

    </link>
    <joint name="right_wrist_2_joint" type="revolute">
        <parent link="right_wrist_1_link" />
        <child link="right_wrist_2_link" />
        <origin rpy="1.570796327 0 0" xyz="0 -0.09465 -1.9413039509e-11" />
        <axis xyz="0 0 1" />
        <limit effort="28.0" lower="-3.14159265359" upper="3.14159265359" velocity="3.2" />
        <dynamics damping="0.0" friction="0.0" />
    </joint>
    <link name="right_wrist_2_link">
        <visual>
            <origin rpy="0 0 0" xyz="0 0 -0.095" />
            <geometry>
                <mesh filename="package://ur_description/meshes/ur5/visual/wrist2.dae" />
            </geometry>
            <material name="LightGrey">
                <color rgba="0.7 0.7 0.7 1.0" />
            </material>
        </visual>
        <collision>
            <origin rpy="0 0 0" xyz="0 0 -0.095" />
            <geometry>
                <mesh filename="package://ur_description/meshes/ur5/collision/wrist2.stl" />
            </geometry>
        </collision>
        
<inertial>
            <mass value="1.219" />
            <origin rpy="0 0 0" xyz="0.0 0.0 0.0" />
            <inertia ixx="0.00178515266177" ixy="0.0" ixz="0.0" iyy="0.00178515266177" iyz="0.0" izz="0.0021942" />
        </inertial>

    </link>
    <joint name="right_wrist_3_joint" type="revolute">
        <parent link="right_wrist_2_link" />
        <child link="right_wrist_3_link" />
        <origin rpy="1.57079632659 3.14159265359 3.14159265359" xyz="0 0.0823 -1.68800121668e-11" />
        <axis xyz="0 0 1" />
        <limit effort="28.0" lower="-3.14159265359" upper="3.14159265359" velocity="3.2" />
        <dynamics damping="0.0" friction="0.0" />
    </joint>
    <link name="right_wrist_3_link">
        <visual>
            <origin rpy="1.57079632679 0 0" xyz="0 0 -0.0818" />
            <geometry>
                <mesh filename="package://ur_description/meshes/ur5/visual/wrist3.dae" />
            </geometry>
            <material name="LightGrey">
                <color rgba="0.7 0.7 0.7 1.0" />
            </material>
        </visual>
        <collision>
            <origin rpy="1.57079632679 0 0" xyz="0 0 -0.0818" />
            <geometry>
                <mesh filename="package://ur_description/meshes/ur5/collision/wrist3.stl" />
            </geometry>
        </collision>
        
<inertial>
            <mass value="0.1879" />
            <origin rpy="0 0 0" xyz="0.0 0.0 -0.01525" />
            <inertia ixx="8.06247260834e-05" ixy="0.0" ixz="0.0" iyy="8.06247260834e-05" iyz="0.0" izz="0.0001321171875" />
        </inertial>

    </link>
    <joint name="right_ee_fixed_joint" type="fixed">
        <parent link="right_wrist_3_link" />
        <child link="right_ee_link" />
        <origin rpy="0.0 -1.57079632679 1.57079632679" xyz="0.0 0.0 0.0" />
    </joint>
    <link name="right_ee_link">
        <collision>
            <geometry>
                <box size="0.01 0.01 0.01" />
            </geometry>
            <origin rpy="0 0 0" xyz="-0.01 0 0" />
        </collision>
        
<inertial>
            <mass value="0.1" />
            <inertia ixx="0.03" iyy="0.03" izz="0.03" ixy="0.0" ixz="0.0" iyz="0.0" />
        </inertial>

    </link>
    <transmission name="right_shoulder_pan_trans">
        <type>transmission_interface/SimpleTransmission</type>
        <joint name="right_shoulder_pan_joint">
            <hardwareInterface>hardware_interface/PositionJointInterface</hardwareInterface>
        </joint>
        <actuator name="right_shoulder_pan_motor">
            <mechanicalReduction>1</mechanicalReduction>
        </actuator>
    </transmission>
    <transmission name="right_shoulder_lift_trans">
        <type>transmission_interface/SimpleTransmission</type>
        <joint name="right_shoulder_lift_joint">
            <hardwareInterface>hardware_interface/PositionJointInterface</hardwareInterface>
        </joint>
        <actuator name="right_shoulder_lift_motor">
            <mechanicalReduction>1</mechanicalReduction>
        </actuator>
    </transmission>
    <transmission name="right_elbow_trans">
        <type>transmission_interface/SimpleTransmission</type>
        <joint name="right_elbow_joint">
            <hardwareInterface>hardware_interface/PositionJointInterface</hardwareInterface>
        </joint>
        <actuator name="right_elbow_motor">
            <mechanicalReduction>1</mechanicalReduction>
        </actuator>
    </transmission>
    <transmission name="right_wrist_1_trans">
        <type>transmission_interface/SimpleTransmission</type>
        <joint name="right_wrist_1_joint">
            <hardwareInterface>hardware_interface/PositionJointInterface</hardwareInterface>
        </joint>
        <actuator name="right_wrist_1_motor">
            <mechanicalReduction>1</mechanicalReduction>
        </actuator>
    </transmission>
    <transmission name="right_wrist_2_trans">
        <type>transmission_interface/SimpleTransmission</type>
        <joint name="right_wrist_2_joint">
            <hardwareInterface>hardware_interface/PositionJointInterface</hardwareInterface>
        </joint>
        <actuator name="right_wrist_2_motor">
            <mechanicalReduction>1</mechanicalReduction>
        </actuator>
    </transmission>
    <transmission name="right_wrist_3_trans">
        <type>transmission_interface/SimpleTransmission</type>
        <joint name="right_wrist_3_joint">
            <hardwareInterface>hardware_interface/PositionJointInterface</hardwareInterface>
        </joint>
        <actuator name="right_wrist_3_motor">
            <mechanicalReduction>1</mechanicalReduction>
        </actuator>
    </transmission>
    <gazebo reference="right_shoulder_link">
        <selfCollide>true</selfCollide>
    </gazebo>
    <gazebo reference="right_upper_arm_link">
        <selfCollide>true</selfCollide>
    </gazebo>
    <gazebo reference="right_forearm_link">
        <selfCollide>true</selfCollide>
    </gazebo>
    <gazebo reference="right_wrist_1_link">
        <selfCollide>true</selfCollide>
    </gazebo>
    <gazebo reference="right_wrist_3_link">
        <selfCollide>true</selfCollide>
    </gazebo>
    <gazebo reference="right_wrist_2_link">
        <selfCollide>true</selfCollide>
    </gazebo>
    <gazebo reference="right_ee_link">
        <selfCollide>true</selfCollide>
    </gazebo>
    <!-- ROS base_link to UR 'Base' Coordinates transform -->
    <link name="right_base" />
    <joint name="right_base_link-base_fixed_joint" type="fixed">
        <!-- NOTE: this rotation is only needed as long as base_link itself is
                 not corrected wrt the real robot (ie: rotated over 180
                 degrees)
      -->
        <origin rpy="0 0 -3.14159265359" xyz="0 0 0" />
        <parent link="right_base_link" />
        <child link="right_base" />
    </joint>
    <!-- Frame coincident with all-zeros TCP on UR controller -->
    <link name="right_tool0" />
    <joint name="right_wrist_3_link-tool0_fixed_joint" type="fixed">
        <origin rpy="-1.57079632679 0 0" xyz="0 0.0823 0" />
        <parent link="right_wrist_3_link" />
        <child link="right_tool0" />
    </joint>
    <link name="world" />
    <link name="ur5_frame">
        <visual>
            <origin rpy="0.0 0 0" xyz="0 0 0" />
            <geometry>
                <mesh filename="package://daurar_description/meshes/Dual_Arm_UR5Frame.STL" />
            </geometry>
        </visual>
        <collision>
            <origin rpy="0.0 0 0" xyz="0 0 0" />
            <geometry>
                <mesh filename="package://daurar_description/meshes/Dual_Arm_UR5Frame.STL" />
            </geometry>
        </collision>
        
<inertial>
            <origin rpy="0.0 0 0" xyz="0 0 0" />
            <mass value="27.2155" />
            <inertia ixx="5.01" ixy="0.0" ixz="0.0" iyy="5.07" iyz="0.0" izz="3.20" />
        </inertial>

    </link>
    <joint name="ur5_frame_to_world" type="fixed">
        <parent link="world" />
        <child link="ur5_frame" />
        <origin rpy="0.0 0.0 0.0" xyz="0.0 0.0 0.0" />
    </joint>
    <!-- right arm -->
    <joint name="world_joint_2" type="fixed">
        <parent link="ur5_frame" />
        <child link="right_base_link" />
        <origin rpy="-0.785398163397 3.14159265359  1.57079632679" xyz="0.265 0.635 1.275" />
    </joint>
    <link name="right_gripper_base_link">
        <visual>
            <geometry>
                <mesh filename="package://robotiq_85_description/meshes/visual/robotiq_85_base_link.dae" />
            </geometry>
        </visual>
        <collision>
            <geometry>
                <mesh filename="package://robotiq_85_description/meshes/collision/robotiq_85_base_link.stl" />
            </geometry>
        </collision>
        
<inertial>
            <mass value="0.636951" />
            <origin xyz="0.0 0.0 0.0" />
            <inertia ixx="0.000380" ixy="0.000000" ixz="0.000000" iyx="0.000000" iyy="0.001110" iyz="0.000000" izx="0.000000" izy="0.000000" izz="0.001171" />
        </inertial>

    </link>
    <joint name="right_gripper_base_joint" type="fixed">
        <parent link="right_ee_link" />
        <child link="right_gripper_base_link" />
        <origin rpy="0 0 0" xyz="0 0 0" />
    </joint>
    <gazebo reference="right_gripper_base_link">
        <implicitSpringDamper>1</implicitSpringDamper>
        <mu1>100000</mu1>
        <mu2>100000</mu2>
        <kp>100000000.0</kp>
        <kd>1.0</kd>
    </gazebo>
    <joint name="right_gripper_finger1_joint" type="revolute">
        <parent link="right_gripper_base_link" />
        <child link="right_gripper_finger1_knuckle_link" />
        <axis xyz="0 0 1" />
        <origin rpy="3.14159265359 0.0 0.0" xyz="0.05490451627 0.03060114443 0.0" />
        <limit effort="1000" lower="0.0" upper="0.804" velocity="2.0" />
    </joint>
    <joint name="right_gripper_finger2_joint" type="revolute">
        <parent link="right_gripper_base_link" />
        <child link="right_gripper_finger2_knuckle_link" />
        <axis xyz="0 0 1" />
        <origin rpy="0.0 0.0 0.0" xyz="0.05490451627 -0.03060114443 0.0" />
        <limit effort="1000" lower="-3.14" upper="3.14" velocity="100.0" />
        <mimic joint="right_gripper_finger1_joint" />
    </joint>
    <link name="right_gripper_finger1_knuckle_link">
        <visual>
            <geometry>
                <mesh filename="package://robotiq_85_description/meshes/visual/robotiq_85_knuckle_link.dae" />
            </geometry>
        </visual>
        <collision>
            <geometry>
                <mesh filename="package://robotiq_85_description/meshes/collision/robotiq_85_knuckle_link.stl" />
            </geometry>
        </collision>
        
<inertial>
            <mass value="0.018491" />
            <origin xyz="0.0 0.0 0.0" />
            <inertia ixx="0.000009" ixy="-0.000001" ixz="0.000000" iyx="-0.000001" iyy="0.000001" iyz="0.000000" izx="0.000000" izy="0.000000" izz="0.000010" />
        </inertial>

    </link>
    <gazebo reference="right_gripper_finger1_knuckle_link">
        <implicitSpringDamper>1</implicitSpringDamper>
        <mu1>100000</mu1>
        <mu2>100000</mu2>
        <kp>100000000.0</kp>
        <kd>1.0</kd>
    </gazebo>
    <link name="right_gripper_finger2_knuckle_link">
        <visual>
            <geometry>
                <mesh filename="package://robotiq_85_description/meshes/visual/robotiq_85_knuckle_link.dae" />
            </geometry>
        </visual>
        <collision>
            <geometry>
                <mesh filename="package://robotiq_85_description/meshes/collision/robotiq_85_knuckle_link.stl" />
            </geometry>
        </collision>
        
<inertial>
            <mass value="0.018491" />
            <origin xyz="0.0 0.0 0.0" />
            <inertia ixx="0.000009" ixy="-0.000001" ixz="0.000000" iyx="-0.000001" iyy="0.000001" iyz="0.000000" izx="0.000000" izy="0.000000" izz="0.000010" />
        </inertial>

    </link>
    <gazebo reference="right_gripper_finger2_knuckle_link">
        <implicitSpringDamper>1</implicitSpringDamper>
        <mu1>100000</mu1>
        <mu2>100000</mu2>
        <kp>100000000.0</kp>
        <kd>1.0</kd>
    </gazebo>
    <joint name="right_gripper_finger1_finger_joint" type="fixed">
        <parent link="right_gripper_finger1_knuckle_link" />
        <child link="right_gripper_finger1_finger_link" />
        <origin rpy="0 0 0" xyz="-0.00408552455 -0.03148604435 0.0" />
    </joint>
    <joint name="right_gripper_finger2_finger_joint" type="fixed">
        <parent link="right_gripper_finger2_knuckle_link" />
        <child link="right_gripper_finger2_finger_link" />
        <origin rpy="0 0 0" xyz="-0.00408552455 -0.03148604435 0.0" />
    </joint>
    <link name="right_gripper_finger1_finger_link">
        <visual>
            <geometry>
                <mesh filename="package://robotiq_85_description/meshes/visual/robotiq_85_finger_link.dae" />
            </geometry>
        </visual>
        <collision>
            <geometry>
                <mesh filename="package://robotiq_85_description/meshes/collision/robotiq_85_finger_link.stl" />
            </geometry>
        </collision>
        
<inertial>
            <mass value="0.027309" />
            <origin xyz="0.0 0.0 0.0" />
            <inertia ixx="0.000003" ixy="-0.000002" ixz="0.000000" iyx="-0.000002" iyy="0.000021" iyz="0.000000" izx="0.000000" izy="0.000000" izz="0.000020" />
        </inertial>

    </link>
    <gazebo reference="right_gripper_finger1_finger_link">
        <implicitSpringDamper>1</implicitSpringDamper>
        <mu1>100000</mu1>
        <mu2>100000</mu2>
        <kp>100000000.0</kp>
        <kd>1.0</kd>
    </gazebo>
    <link name="right_gripper_finger2_finger_link">
        <visual>
            <geometry>
                <mesh filename="package://robotiq_85_description/meshes/visual/robotiq_85_finger_link.dae" />
            </geometry>
        </visual>
        <collision>
            <geometry>
                <mesh filename="package://robotiq_85_description/meshes/collision/robotiq_85_finger_link.stl" />
            </geometry>
        </collision>
        
<inertial>
            <mass value="0.027309" />
            <origin xyz="0.0 0.0 0.0" />
            <inertia ixx="0.000003" ixy="-0.000002" ixz="0.000000" iyx="-0.000002" iyy="0.000021" iyz="0.000000" izx="0.000000" izy="0.000000" izz="0.000020" />
        </inertial>

    </link>
    <gazebo reference="right_gripper_finger2_finger_link">
        <implicitSpringDamper>1</implicitSpringDamper>
        <mu1>100000</mu1>
        <mu2>100000</mu2>
        <kp>100000000.0</kp>
        <kd>1.0</kd>
    </gazebo>
    <joint name="right_gripper_finger1_inner_knuckle_joint" type="continuous">
        <parent link="right_gripper_base_link" />
        <child link="right_gripper_finger1_inner_knuckle_link" />
        <axis xyz="0 0 1" />
        <origin rpy="3.14159265359 0.0 0.0" xyz="0.06142 0.0127 0" />
        <limit effort="0.1" lower="-3.14" upper="3.14" velocity="100.0" />
        <mimic joint="right_gripper_finger1_joint" offset="0" />
    </joint>
    <joint name="right_gripper_finger2_inner_knuckle_joint" type="continuous">
        <parent link="right_gripper_base_link" />
        <child link="right_gripper_finger2_inner_knuckle_link" />
        <axis xyz="0 0 1" />
        <origin rpy="0 0 0" xyz="0.06142 -0.0127 0" />
        <limit effort="0.1" lower="-3.14" upper="3.14" velocity="100.0" />
        <mimic joint="right_gripper_finger1_joint" offset="0" />
    </joint>
    <link name="right_gripper_finger1_inner_knuckle_link">
        <visual>
            <geometry>
                <mesh filename="package://robotiq_85_description/meshes/visual/robotiq_85_inner_knuckle_link.dae" />
            </geometry>
        </visual>
        <collision>
            <geometry>
                <mesh filename="package://robotiq_85_description/meshes/collision/robotiq_85_inner_knuckle_link.stl" />
            </geometry>
        </collision>
        
<inertial>
            <mass value="0.029951" />
            <origin xyz="0.0 0.0 0.0" />
            <inertia ixx="0.000039" ixy="0.000000" ixz="0.000000" iyx="0.000000" iyy="0.000005" iyz="0.000000" izx="0.000000" izy="0.000000" izz="0.000035" />
        </inertial>

    </link>
    <gazebo reference="right_gripper_finger1_inner_knuckle_link">
        <implicitSpringDamper>1</implicitSpringDamper>
        <mu1>100000</mu1>
        <mu2>100000</mu2>
        <kp>100000000.0</kp>
        <kd>1.0</kd>
    </gazebo>
    <link name="right_gripper_finger2_inner_knuckle_link">
        <visual>
            <geometry>
                <mesh filename="package://robotiq_85_description/meshes/visual/robotiq_85_inner_knuckle_link.dae" />
            </geometry>
        </visual>
        <collision>
            <geometry>
                <mesh filename="package://robotiq_85_description/meshes/collision/robotiq_85_inner_knuckle_link.stl" />
            </geometry>
        </collision>
        
<inertial>
            <mass value="0.029951" />
            <origin xyz="0.0 0.0 0.0" />
            <inertia ixx="0.000039" ixy="0.000000" ixz="0.000000" iyx="0.000000" iyy="0.000005" iyz="0.000000" izx="0.000000" izy="0.000000" izz="0.000035" />
        </inertial>

    </link>
    <gazebo reference="right_gripper_finger2_inner_knuckle_link">
        <implicitSpringDamper>1</implicitSpringDamper>
        <mu1>100000</mu1>
        <mu2>100000</mu2>
        <kp>100000000.0</kp>
        <kd>1.0</kd>
    </gazebo>
    <joint name="right_gripper_finger1_finger_tip_joint" type="continuous">
        <parent link="right_gripper_finger1_inner_knuckle_link" />
        <child link="right_gripper_finger1_finger_tip_link" />
        <axis xyz="0 0 1" />
        <origin rpy="0.0 0.0 0.0" xyz="0.04303959807 -0.03759940821 0.0" />
        <limit effort="0.1" lower="-3.14" upper="3.14" velocity="100.0" />
        <mimic joint="right_gripper_finger1_joint" multiplier="-1" />
    </joint>
    <joint name="right_gripper_finger2_finger_tip_joint" type="continuous">
        <parent link="right_gripper_finger2_inner_knuckle_link" />
        <child link="right_gripper_finger2_finger_tip_link" />
        <axis xyz="0 0 1" />
        <origin rpy="0.0 0.0 0.0" xyz="0.04303959807 -0.03759940821  0.0" />
        <limit effort="0.1" lower="-3.14" upper="3.14" velocity="100.0" />
        <mimic joint="right_gripper_finger1_joint" multiplier="-1" />
    </joint>
    <link name="right_gripper_finger1_finger_tip_link">
        <visual>
            <geometry>
                <mesh filename="package://robotiq_85_description/meshes/visual/robotiq_85_finger_tip_link.dae" />
            </geometry>
        </visual>
        <collision>
            <geometry>
                <mesh filename="package://robotiq_85_description/meshes/collision/robotiq_85_finger_tip_link.stl" />
            </geometry>
        </collision>
        
<inertial>
            <mass value="0.019555" />
            <origin xyz="0.0 0.0 0.0" />
            <inertia ixx="0.000002" ixy="0.000000" ixz="0.000000" iyx="0.000000" iyy="0.000005" iyz="0.000000" izx="0.000000" izy="0.000000" izz="0.000006" />
        </inertial>

    </link>
    <gazebo reference="right_gripper_finger1_finger_tip_link">
        <implicitSpringDamper>1</implicitSpringDamper>
        <mu1>100000</mu1>
        <mu2>100000</mu2>
        <kp>100000000.0</kp>
        <kd>1.0</kd>
    </gazebo>
    <link name="right_gripper_finger2_finger_tip_link">
        <visual>
            <geometry>
                <mesh filename="package://robotiq_85_description/meshes/visual/robotiq_85_finger_tip_link.dae" />
            </geometry>
        </visual>
        <collision>
            <geometry>
                <mesh filename="package://robotiq_85_description/meshes/collision/robotiq_85_finger_tip_link.stl" />
            </geometry>
        </collision>
        
<inertial>
            <mass value="0.019555" />
            <origin xyz="0.0 0.0 0.0" />
            <inertia ixx="0.000002" ixy="0.000000" ixz="0.000000" iyx="0.000000" iyy="0.000005" iyz="0.000000" izx="0.000000" izy="0.000000" izz="0.000006" />
        </inertial>

    </link>
    <gazebo reference="right_gripper_finger2_finger_tip_link">
        <implicitSpringDamper>1</implicitSpringDamper>
        <mu1>100000</mu1>
        <mu2>100000</mu2>
        <kp>100000000.0</kp>
        <kd>1.0</kd>
    </gazebo>
    <gazebo>
        <plugin filename="libgazebo_grasp_fix.so" name="gazebo_grasp_fix">
            <arm>
                <arm_name>gripper_arm</arm_name>
                <palm_link>right_ee_link</palm_link>
                <gripper_link>right_gripper_finger1_finger_tip_link</gripper_link>
                <gripper_link>right_gripper_finger2_finger_tip_link</gripper_link>
            </arm>
            <forces_angle_tolerance>100</forces_angle_tolerance>
            <update_rate>2</update_rate>
            <grip_count_threshold>1</grip_count_threshold>
            <max_grip_count>2</max_grip_count>
            <release_tolerance>0.005</release_tolerance>
            <disable_collisions_on_attach>true</disable_collisions_on_attach>
            <contact_topic>__default_topic__</contact_topic>
        </plugin>
    </gazebo>
    <transmission name="right_gripper_finger1_trans">
        <type>transmission_interface/SimpleTransmission</type>
        <joint name="right_gripper_finger1_joint">
            <hardwareInterface>PositionJointInterface</hardwareInterface>
        </joint>
        <actuator name="right_gripper_finger1_motor">
            <mechanicalReduction>1</mechanicalReduction>
            <hardwareInterface>PositionJointInterface</hardwareInterface>
        </actuator>
    </transmission>
    <gazebo>
        <!-- loading plugin: mimic joints works in gazebo now -->
        <plugin filename="libroboticsgroup_gazebo_mimic_joint_plugin.so" name="right_mimic_robotiq_85_1">
            <joint>right_gripper_finger1_joint</joint>
            <mimicJoint>right_gripper_finger2_joint</mimicJoint>
            <!--multiplier>1.0</multiplier>
                <offset>0.0</offset-->
        </plugin>
        <plugin filename="libroboticsgroup_gazebo_mimic_joint_plugin.so" name="right_mimic_robotiq_85_2">
            <joint>right_gripper_finger1_joint</joint>
            <mimicJoint>right_gripper_finger2_inner_knuckle_joint</mimicJoint>
            <!--multiplier>1.0</multiplier>
                <offset>0.0</offset-->
        </plugin>
        <plugin filename="libroboticsgroup_gazebo_mimic_joint_plugin.so" name="right_mimic_robotiq_85_3">
            <joint>right_gripper_finger1_joint</joint>
            <mimicJoint>right_gripper_finger1_inner_knuckle_joint</mimicJoint>
            <!--multiplier>1.0</multiplier>
                <offset>0.0</offset-->
        </plugin>
        <plugin filename="libroboticsgroup_gazebo_mimic_joint_plugin.so" name="right_mimic_robotiq_85_4">
            <joint>right_gripper_finger1_joint</joint>
            <mimicJoint>right_gripper_finger1_finger_tip_joint</mimicJoint>
            <multiplier>-1.0</multiplier>
            <offset>0.0</offset>
        </plugin>
        <plugin filename="libroboticsgroup_gazebo_mimic_joint_plugin.so" name="right_mimic_robotiq_85_5">
            <joint>right_gripper_finger1_joint</joint>
            <mimicJoint>right_gripper_finger2_finger_tip_joint</mimicJoint>
            <multiplier>-1.0</multiplier>
            <offset>0.0</offset>
        </plugin>
    </gazebo>
    <transmission name="trans_right_shoulder_pan_joint">
        <type>transmission_interface/SimpleTransmission</type>
        <joint name="right_shoulder_pan_joint">
            <hardwareInterface>hardware_interface/EffortJointInterface</hardwareInterface>
        </joint>
        <actuator name="right_shoulder_pan_joint_motor">
            <hardwareInterface>hardware_interface/EffortJointInterface</hardwareInterface>
            <mechanicalReduction>1</mechanicalReduction>
        </actuator>
    </transmission>
    <transmission name="trans_right_shoulder_lift_joint">
        <type>transmission_interface/SimpleTransmission</type>
        <joint name="right_shoulder_lift_joint">
            <hardwareInterface>hardware_interface/EffortJointInterface</hardwareInterface>
        </joint>
        <actuator name="right_shoulder_lift_joint_motor">
            <hardwareInterface>hardware_interface/EffortJointInterface</hardwareInterface>
            <mechanicalReduction>1</mechanicalReduction>
        </actuator>
    </transmission>
    <transmission name="trans_right_elbow_joint">
        <type>transmission_interface/SimpleTransmission</type>
        <joint name="right_elbow_joint">
            <hardwareInterface>hardware_interface/EffortJointInterface</hardwareInterface>
        </joint>
        <actuator name="right_elbow_joint_motor">
            <hardwareInterface>hardware_interface/EffortJointInterface</hardwareInterface>
            <mechanicalReduction>1</mechanicalReduction>
        </actuator>
    </transmission>
    <transmission name="trans_right_wrist_1_joint">
        <type>transmission_interface/SimpleTransmission</type>
        <joint name="right_wrist_1_joint">
            <hardwareInterface>hardware_interface/EffortJointInterface</hardwareInterface>
        </joint>
        <actuator name="right_wrist_1_joint_motor">
            <hardwareInterface>hardware_interface/EffortJointInterface</hardwareInterface>
            <mechanicalReduction>1</mechanicalReduction>
        </actuator>
    </transmission>
    <transmission name="trans_right_wrist_2_joint">
        <type>transmission_interface/SimpleTransmission</type>
        <joint name="right_wrist_2_joint">
            <hardwareInterface>hardware_interface/EffortJointInterface</hardwareInterface>
        </joint>
        <actuator name="right_wrist_2_joint_motor">
            <hardwareInterface>hardware_interface/EffortJointInterface</hardwareInterface>
            <mechanicalReduction>1</mechanicalReduction>
        </actuator>
    </transmission>
    <transmission name="trans_right_wrist_3_joint">
        <type>transmission_interface/SimpleTransmission</type>
        <joint name="right_wrist_3_joint">
            <hardwareInterface>hardware_interface/EffortJointInterface</hardwareInterface>
        </joint>
        <actuator name="right_wrist_3_joint_motor">
            <hardwareInterface>hardware_interface/EffortJointInterface</hardwareInterface>
            <mechanicalReduction>1</mechanicalReduction>
        </actuator>
    </transmission>
    <transmission name="trans_right_gripper_finger1_joint">
        <type>transmission_interface/SimpleTransmission</type>
        <joint name="right_gripper_finger1_joint">
            <hardwareInterface>hardware_interface/EffortJointInterface</hardwareInterface>
        </joint>
        <actuator name="right_gripper_finger1_joint_motor">
            <hardwareInterface>hardware_interface/EffortJointInterface</hardwareInterface>
            <mechanicalReduction>1</mechanicalReduction>
        </actuator>
    </transmission>
    <transmission name="trans_right_gripper_finger2_joint">
        <type>transmission_interface/SimpleTransmission</type>
        <joint name="right_gripper_finger2_joint">
            <hardwareInterface>hardware_interface/EffortJointInterface</hardwareInterface>
        </joint>
        <actuator name="right_gripper_finger2_joint_motor">
            <hardwareInterface>hardware_interface/EffortJointInterface</hardwareInterface>
            <mechanicalReduction>1</mechanicalReduction>
        </actuator>
    </transmission>
    <transmission name="trans_right_gripper_finger1_inner_knuckle_joint">
        <type>transmission_interface/SimpleTransmission</type>
        <joint name="right_gripper_finger1_inner_knuckle_joint">
            <hardwareInterface>hardware_interface/EffortJointInterface</hardwareInterface>
        </joint>
        <actuator name="right_gripper_finger1_inner_knuckle_joint_motor">
            <hardwareInterface>hardware_interface/EffortJointInterface</hardwareInterface>
            <mechanicalReduction>1</mechanicalReduction>
        </actuator>
    </transmission>
    <transmission name="trans_right_gripper_finger2_inner_knuckle_joint">
        <type>transmission_interface/SimpleTransmission</type>
        <joint name="right_gripper_finger2_inner_knuckle_joint">
            <hardwareInterface>hardware_interface/EffortJointInterface</hardwareInterface>
        </joint>
        <actuator name="right_gripper_finger2_inner_knuckle_joint_motor">
            <hardwareInterface>hardware_interface/EffortJointInterface</hardwareInterface>
            <mechanicalReduction>1</mechanicalReduction>
        </actuator>
    </transmission>
    <transmission name="trans_right_gripper_finger1_finger_tip_joint">
        <type>transmission_interface/SimpleTransmission</type>
        <joint name="right_gripper_finger1_finger_tip_joint">
            <hardwareInterface>hardware_interface/EffortJointInterface</hardwareInterface>
        </joint>
        <actuator name="right_gripper_finger1_finger_tip_joint_motor">
            <hardwareInterface>hardware_interface/EffortJointInterface</hardwareInterface>
            <mechanicalReduction>1</mechanicalReduction>
        </actuator>
    </transmission>
    <transmission name="trans_right_gripper_finger2_finger_tip_joint">
        <type>transmission_interface/SimpleTransmission</type>
        <joint name="right_gripper_finger2_finger_tip_joint">
            <hardwareInterface>hardware_interface/EffortJointInterface</hardwareInterface>
        </joint>
        <actuator name="right_gripper_finger2_finger_tip_joint_motor">
            <hardwareInterface>hardware_interface/EffortJointInterface</hardwareInterface>
            <mechanicalReduction>1</mechanicalReduction>
        </actuator>
    </transmission>
    <gazebo>
        <plugin name="gazebo_ros_control" filename="libgazebo_ros_control.so">
            <robotNamespace>/</robotNamespace>
        </plugin>
    </gazebo>
</robot>

<transmission name="right_shoulder_pan_trans">
        <type>transmission_interface/SimpleTransmission</type>
        <joint name="right_shoulder_pan_joint">
            <hardwareInterface>hardware_interface/PositionJointInterface</hardwareInterface>
        </joint>
        <actuator name="right_shoulder_pan_motor">
            <mechanicalReduction>1</mechanicalReduction>
        </actuator>
    </transmission>
    <transmission name="right_shoulder_lift_trans">
        <type>transmission_interface/SimpleTransmission</type>
        <joint name="right_shoulder_lift_joint">
            <hardwareInterface>hardware_interface/PositionJointInterface</hardwareInterface>
        </joint>
        <actuator name="right_shoulder_lift_motor">
            <mechanicalReduction>1</mechanicalReduction>
        </actuator>
    </transmission>
    <transmission name="right_elbow_trans">
        <type>transmission_interface/SimpleTransmission</type>
        <joint name="right_elbow_joint">
            <hardwareInterface>hardware_interface/PositionJointInterface</hardwareInterface>
        </joint>
        <actuator name="right_elbow_motor">
            <mechanicalReduction>1</mechanicalReduction>
        </actuator>
    </transmission>
    <transmission name="right_wrist_1_trans">
        <type>transmission_interface/SimpleTransmission</type>
        <joint name="right_wrist_1_joint">
            <hardwareInterface>hardware_interface/PositionJointInterface</hardwareInterface>
        </joint>
        <actuator name="right_wrist_1_motor">
            <mechanicalReduction>1</mechanicalReduction>
        </actuator>
    </transmission>
    <transmission name="right_wrist_2_trans">
        <type>transmission_interface/SimpleTransmission</type>
        <joint name="right_wrist_2_joint">
            <hardwareInterface>hardware_interface/PositionJointInterface</hardwareInterface>
        </joint>
        <actuator name="right_wrist_2_motor">
            <mechanicalReduction>1</mechanicalReduction>
        </actuator>
    </transmission>
    <transmission name="right_wrist_3_trans">
        <type>transmission_interface/SimpleTransmission</type>
        <joint name="right_wrist_3_joint">
            <hardwareInterface>hardware_interface/PositionJointInterface</hardwareInterface>
        </joint>
        <actuator name="right_wrist_3_motor">
            <mechanicalReduction>1</mechanicalReduction>
        </actuator>
    </transmission>
    <gazebo reference="right_shoulder_link">
        <selfCollide>true</selfCollide>
    </gazebo>
    <gazebo reference="right_upper_arm_link">
        <selfCollide>true</selfCollide>
    </gazebo>
    <gazebo reference="right_forearm_link">
        <selfCollide>true</selfCollide>
    </gazebo>
    <gazebo reference="right_wrist_1_link">
        <selfCollide>true</selfCollide>
    </gazebo>
    <gazebo reference="right_wrist_3_link">
        <selfCollide>true</selfCollide>
    </gazebo>
    <gazebo reference="right_wrist_2_link">
        <selfCollide>true</selfCollide>
    </gazebo>
    <gazebo reference="right_ee_link">
        <selfCollide>true</selfCollide>
    </gazebo>
    <!-- ROS base_link to UR 'Base' Coordinates transform -->
    <link name="right_base" />
    <joint name="right_base_link-base_fixed_joint" type="fixed">
        <!-- NOTE: this rotation is only needed as long as base_link itself is
                 not corrected wrt the real robot (ie: rotated over 180
                 degrees)
      -->
        <origin rpy="0 0 -3.14159265359" xyz="0 0 0" />
        <parent link="right_base_link" />
        <child link="right_base" />
    </joint>
    <!-- Frame coincident with all-zeros TCP on UR controller -->
    <link name="right_tool0" />
    <joint name="right_wrist_3_link-tool0_fixed_joint" type="fixed">
        <origin rpy="-1.57079632679 0 0" xyz="0 0.0823 0" />
        <parent link="right_wrist_3_link" />
        <child link="right_tool0" />
    </joint>
    <link name="world" />
    <link name="ur5_frame">
        <visual>
            <origin rpy="0.0 0 0" xyz="0 0 0" />
            <geometry>
                <mesh filename="package://daurar_description/meshes/Dual_Arm_UR5Frame.STL" />
            </geometry>
        </visual>
        <collision>
            <origin rpy="0.0 0 0" xyz="0 0 0" />
            <geometry>
                <mesh filename="package://daurar_description/meshes/Dual_Arm_UR5Frame.STL" />
            </geometry>
        </collision>
        <inertial>
            <origin rpy="0.0 0 0" xyz="0 0 0" />
            <mass value="27.2155" />
            <inertia ixx="5.01" ixy="0.0" ixz="0.0" iyy="5.07" iyz="0.0" izz="3.20" />
        </inertial>
    </link>
    <joint name="ur5_frame_to_world" type="fixed">
        <parent link="world" />
        <child link="ur5_frame" />
        <origin rpy="0.0 0.0 0.0" xyz="0.0 0.0 0.0" />
    </joint>
    <!-- right arm -->
    <joint name="world_joint_2" type="fixed">
        <parent link="ur5_frame" />
        <child link="right_base_link" />
        <origin rpy="-0.785398163397 3.14159265359  1.57079632679" xyz="0.265 0.635 1.275" />
    </joint>
    <link name="right_gripper_base_link">
        <visual>
            <geometry>
                <mesh filename="package://robotiq_85_description/meshes/visual/robotiq_85_base_link.dae" />
            </geometry>
        </visual>
        <collision>
            <geometry>
                <mesh filename="package://robotiq_85_description/meshes/collision/robotiq_85_base_link.stl" />
            </geometry>
        </collision>
        <inertial>
            <mass value="0.636951" />
            <origin xyz="0.0 0.0 0.0" />
            <inertia ixx="0.000380" ixy="0.000000" ixz="0.000000" iyx="0.000000" iyy="0.001110" iyz="0.000000" izx="0.000000" izy="0.000000" izz="0.001171" />
        </inertial>
    </link>
    <joint name="right_gripper_base_joint" type="fixed">
        <parent link="right_ee_link" />
        <child link="right_gripper_base_link" />
        <origin rpy="0 0 0" xyz="0 0 0" />
    </joint>
    <gazebo reference="right_gripper_base_link">
        <implicitSpringDamper>1</implicitSpringDamper>
        <mu1>100000</mu1>
        <mu2>100000</mu2>
        <kp>100000000.0</kp>
        <kd>1.0</kd>
    </gazebo>
    <joint name="right_gripper_finger1_joint" type="revolute">
        <parent link="right_gripper_base_link" />
        <child link="right_gripper_finger1_knuckle_link" />
        <axis xyz="0 0 1" />
        <origin rpy="3.14159265359 0.0 0.0" xyz="0.05490451627 0.03060114443 0.0" />
        <limit effort="1000" lower="0.0" upper="0.804" velocity="2.0" />
    </joint>
    <joint name="right_gripper_finger2_joint" type="revolute">
        <parent link="right_gripper_base_link" />
        <child link="right_gripper_finger2_knuckle_link" />
        <axis xyz="0 0 1" />
        <origin rpy="0.0 0.0 0.0" xyz="0.05490451627 -0.03060114443 0.0" />
        <limit effort="1000" lower="-3.14" upper="3.14" velocity="100.0" />
        <mimic joint="right_gripper_finger1_joint" />
    </joint>
    <link name="right_gripper_finger1_knuckle_link">
        <visual>
            <geometry>
                <mesh filename="package://robotiq_85_description/meshes/visual/robotiq_85_knuckle_link.dae" />
            </geometry>
        </visual>
        <collision>
            <geometry>
                <mesh filename="package://robotiq_85_description/meshes/collision/robotiq_85_knuckle_link.stl" />
            </geometry>
        </collision>
        <inertial>
            <mass value="0.018491" />
            <origin xyz="0.0 0.0 0.0" />
            <inertia ixx="0.000009" ixy="-0.000001" ixz="0.000000" iyx="-0.000001" iyy="0.000001" iyz="0.000000" izx="0.000000" izy="0.000000" izz="0.000010" />
        </inertial>
    </link>
    <gazebo reference="right_gripper_finger1_knuckle_link">
        <implicitSpringDamper>1</implicitSpringDamper>
        <mu1>100000</mu1>
        <mu2>100000</mu2>
        <kp>100000000.0</kp>
        <kd>1.0</kd>
    </gazebo>
    <link name="right_gripper_finger2_knuckle_link">
        <visual>
            <geometry>
                <mesh filename="package://robotiq_85_description/meshes/visual/robotiq_85_knuckle_link.dae" />
            </geometry>
        </visual>
        <collision>
            <geometry>
                <mesh filename="package://robotiq_85_description/meshes/collision/robotiq_85_knuckle_link.stl" />
            </geometry>
        </collision>
        <inertial>
            <mass value="0.018491" />
            <origin xyz="0.0 0.0 0.0" />
            <inertia ixx="0.000009" ixy="-0.000001" ixz="0.000000" iyx="-0.000001" iyy="0.000001" iyz="0.000000" izx="0.000000" izy="0.000000" izz="0.000010" />
        </inertial>
    </link>
    <gazebo reference="right_gripper_finger2_knuckle_link">
        <implicitSpringDamper>1</implicitSpringDamper>
        <mu1>100000</mu1>
        <mu2>100000</mu2>
        <kp>100000000.0</kp>
        <kd>1.0</kd>
    </gazebo>
    <joint name="right_gripper_finger1_finger_joint" type="fixed">
        <parent link="right_gripper_finger1_knuckle_link" />
        <child link="right_gripper_finger1_finger_link" />
        <origin rpy="0 0 0" xyz="-0.00408552455 -0.03148604435 0.0" />
    </joint>
    <joint name="right_gripper_finger2_finger_joint" type="fixed">
        <parent link="right_gripper_finger2_knuckle_link" />
        <child link="right_gripper_finger2_finger_link" />
        <origin rpy="0 0 0" xyz="-0.00408552455 -0.03148604435 0.0" />
    </joint>
    <link name="right_gripper_finger1_finger_link">
        <visual>
            <geometry>
                <mesh filename="package://robotiq_85_description/meshes/visual/robotiq_85_finger_link.dae" />
            </geometry>
        </visual>
        <collision>
            <geometry>
                <mesh filename="package://robotiq_85_description/meshes/collision/robotiq_85_finger_link.stl" />
            </geometry>
        </collision>
        <inertial>
            <mass value="0.027309" />
            <origin xyz="0.0 0.0 0.0" />
            <inertia ixx="0.000003" ixy="-0.000002" ixz="0.000000" iyx="-0.000002" iyy="0.000021" iyz="0.000000" izx="0.000000" izy="0.000000" izz="0.000020" />
        </inertial>
    </link>
    <gazebo reference="right_gripper_finger1_finger_link">
        <implicitSpringDamper>1</implicitSpringDamper>
        <mu1>100000</mu1>
        <mu2>100000</mu2>
        <kp>100000000.0</kp>
        <kd>1.0</kd>
    </gazebo>
    <link name="right_gripper_finger2_finger_link">
        <visual>
            <geometry>
                <mesh filename="package://robotiq_85_description/meshes/visual/robotiq_85_finger_link.dae" />
            </geometry>
        </visual>
        <collision>
            <geometry>
                <mesh filename="package://robotiq_85_description/meshes/collision/robotiq_85_finger_link.stl" />
            </geometry>
        </collision>
        <inertial>
            <mass value="0.027309" />
            <origin xyz="0.0 0.0 0.0" />
            <inertia ixx="0.000003" ixy="-0.000002" ixz="0.000000" iyx="-0.000002" iyy="0.000021" iyz="0.000000" izx="0.000000" izy="0.000000" izz="0.000020" />
        </inertial>
    </link>
    <gazebo reference="right_gripper_finger2_finger_link">
        <implicitSpringDamper>1</implicitSpringDamper>
        <mu1>100000</mu1>
        <mu2>100000</mu2>
        <kp>100000000.0</kp>
        <kd>1.0</kd>
    </gazebo>
    <joint name="right_gripper_finger1_inner_knuckle_joint" type="continuous">
        <parent link="right_gripper_base_link" />
        <child link="right_gripper_finger1_inner_knuckle_link" />
        <axis xyz="0 0 1" />
        <origin rpy="3.14159265359 0.0 0.0" xyz="0.06142 0.0127 0" />
        <limit effort="0.1" lower="-3.14" upper="3.14" velocity="100.0" />
        <mimic joint="right_gripper_finger1_joint" offset="0" />
    </joint>
    <joint name="right_gripper_finger2_inner_knuckle_joint" type="continuous">
        <parent link="right_gripper_base_link" />
        <child link="right_gripper_finger2_inner_knuckle_link" />
        <axis xyz="0 0 1" />
        <origin rpy="0 0 0" xyz="0.06142 -0.0127 0" />
        <limit effort="0.1" lower="-3.14" upper="3.14" velocity="100.0" />
        <mimic joint="right_gripper_finger1_joint" offset="0" />
    </joint>
    <link name="right_gripper_finger1_inner_knuckle_link">
        <visual>
            <geometry>
                <mesh filename="package://robotiq_85_description/meshes/visual/robotiq_85_inner_knuckle_link.dae" />
            </geometry>
        </visual>
        <collision>
            <geometry>
                <mesh filename="package://robotiq_85_description/meshes/collision/robotiq_85_inner_knuckle_link.stl" />
            </geometry>
        </collision>
        <inertial>
            <mass value="0.029951" />
            <origin xyz="0.0 0.0 0.0" />
            <inertia ixx="0.000039" ixy="0.000000" ixz="0.000000" iyx="0.000000" iyy="0.000005" iyz="0.000000" izx="0.000000" izy="0.000000" izz="0.000035" />
        </inertial>
    </link>
    <gazebo reference="right_gripper_finger1_inner_knuckle_link">
        <implicitSpringDamper>1</implicitSpringDamper>
        <mu1>100000</mu1>
        <mu2>100000</mu2>
        <kp>100000000.0</kp>
        <kd>1.0</kd>
    </gazebo>
    <link name="right_gripper_finger2_inner_knuckle_link">
        <visual>
            <geometry>
                <mesh filename="package://robotiq_85_description/meshes/visual/robotiq_85_inner_knuckle_link.dae" />
            </geometry>
        </visual>
        <collision>
            <geometry>
                <mesh filename="package://robotiq_85_description/meshes/collision/robotiq_85_inner_knuckle_link.stl" />
            </geometry>
        </collision>
        <inertial>
            <mass value="0.029951" />
            <origin xyz="0.0 0.0 0.0" />
            <inertia ixx="0.000039" ixy="0.000000" ixz="0.000000" iyx="0.000000" iyy="0.000005" iyz="0.000000" izx="0.000000" izy="0.000000" izz="0.000035" />
        </inertial>
    </link>
    <gazebo reference="right_gripper_finger2_inner_knuckle_link">
        <implicitSpringDamper>1</implicitSpringDamper>
        <mu1>100000</mu1>
        <mu2>100000</mu2>
        <kp>100000000.0</kp>
        <kd>1.0</kd>
    </gazebo>
    <joint name="right_gripper_finger1_finger_tip_joint" type="continuous">
        <parent link="right_gripper_finger1_inner_knuckle_link" />
        <child link="right_gripper_finger1_finger_tip_link" />
        <axis xyz="0 0 1" />
        <origin rpy="0.0 0.0 0.0" xyz="0.04303959807 -0.03759940821 0.0" />
        <limit effort="0.1" lower="-3.14" upper="3.14" velocity="100.0" />
        <mimic joint="right_gripper_finger1_joint" multiplier="-1" />
    </joint>
    <joint name="right_gripper_finger2_finger_tip_joint" type="continuous">
        <parent link="right_gripper_finger2_inner_knuckle_link" />
        <child link="right_gripper_finger2_finger_tip_link" />
        <axis xyz="0 0 1" />
        <origin rpy="0.0 0.0 0.0" xyz="0.04303959807 -0.03759940821  0.0" />
        <limit effort="0.1" lower="-3.14" upper="3.14" velocity="100.0" />
        <mimic joint="right_gripper_finger1_joint" multiplier="-1" />
    </joint>
    <link name="right_gripper_finger1_finger_tip_link">
        <visual>
            <geometry>
                <mesh filename="package://robotiq_85_description/meshes/visual/robotiq_85_finger_tip_link.dae" />
            </geometry>
        </visual>
        <collision>
            <geometry>
                <mesh filename="package://robotiq_85_description/meshes/collision/robotiq_85_finger_tip_link.stl" />
            </geometry>
        </collision>
        <inertial>
            <mass value="0.019555" />
            <origin xyz="0.0 0.0 0.0" />
            <inertia ixx="0.000002" ixy="0.000000" ixz="0.000000" iyx="0.000000" iyy="0.000005" iyz="0.000000" izx="0.000000" izy="0.000000" izz="0.000006" />
        </inertial>
    </link>
    <gazebo reference="right_gripper_finger1_finger_tip_link">
        <implicitSpringDamper>1</implicitSpringDamper>
        <mu1>100000</mu1>
        <mu2>100000</mu2>
        <kp>100000000.0</kp>
        <kd>1.0</kd>
    </gazebo>
    <link name="right_gripper_finger2_finger_tip_link">
        <visual>
            <geometry>
                <mesh filename="package://robotiq_85_description/meshes/visual/robotiq_85_finger_tip_link.dae" />
            </geometry>
        </visual>
        <collision>
            <geometry>
                <mesh filename="package://robotiq_85_description/meshes/collision/robotiq_85_finger_tip_link.stl" />
            </geometry>
        </collision>
        <inertial>
            <mass value="0.019555" />
            <origin xyz="0.0 0.0 0.0" />
            <inertia ixx="0.000002" ixy="0.000000" ixz="0.000000" iyx="0.000000" iyy="0.000005" iyz="0.000000" izx="0.000000" izy="0.000000" izz="0.000006" />
        </inertial>
    </link>
    <gazebo reference="right_gripper_finger2_finger_tip_link">
        <implicitSpringDamper>1</implicitSpringDamper>
        <mu1>100000</mu1>
        <mu2>100000</mu2>
        <kp>100000000.0</kp>
        <kd>1.0</kd>
    </gazebo>
    <gazebo>
        <plugin filename="libgazebo_grasp_fix.so" name="gazebo_grasp_fix">
            <arm>
                <arm_name>gripper_arm</arm_name>
                <palm_link>right_ee_link</palm_link>
                <gripper_link>right_gripper_finger1_finger_tip_link</gripper_link>
                <gripper_link>right_gripper_finger2_finger_tip_link</gripper_link>
            </arm>
            <forces_angle_tolerance>100</forces_angle_tolerance>
            <update_rate>2</update_rate>
            <grip_count_threshold>1</grip_count_threshold>
            <max_grip_count>2</max_grip_count>
            <release_tolerance>0.005</release_tolerance>
            <disable_collisions_on_attach>true</disable_collisions_on_attach>
            <contact_topic>__default_topic__</contact_topic>
        </plugin>
    </gazebo>
    <transmission name="right_gripper_finger1_trans">
        <type>transmission_interface/SimpleTransmission</type>
        <joint name="right_gripper_finger1_joint">
            <hardwareInterface>PositionJointInterface</hardwareInterface>
        </joint>
        <actuator name="right_gripper_finger1_motor">
            <mechanicalReduction>1</mechanicalReduction>
            <hardwareInterface>PositionJointInterface</hardwareInterface>
        </actuator>
    </transmission>
    <gazebo>
        <!-- loading plugin: mimic joints works in gazebo now -->
        <plugin filename="libroboticsgroup_gazebo_mimic_joint_plugin.so" name="right_mimic_robotiq_85_1">
            <joint>right_gripper_finger1_joint</joint>
            <mimicJoint>right_gripper_finger2_joint</mimicJoint>
            <!--multiplier>1.0</multiplier>
                <offset>0.0</offset-->
        </plugin>
        <plugin filename="libroboticsgroup_gazebo_mimic_joint_plugin.so" name="right_mimic_robotiq_85_2">
            <joint>right_gripper_finger1_joint</joint>
            <mimicJoint>right_gripper_finger2_inner_knuckle_joint</mimicJoint>
            <!--multiplier>1.0</multiplier>
                <offset>0.0</offset-->
        </plugin>
        <plugin filename="libroboticsgroup_gazebo_mimic_joint_plugin.so" name="right_mimic_robotiq_85_3">
            <joint>right_gripper_finger1_joint</joint>
            <mimicJoint>right_gripper_finger1_inner_knuckle_joint</mimicJoint>
            <!--multiplier>1.0</multiplier>
                <offset>0.0</offset-->
        </plugin>
        <plugin filename="libroboticsgroup_gazebo_mimic_joint_plugin.so" name="right_mimic_robotiq_85_4">
            <joint>right_gripper_finger1_joint</joint>
            <mimicJoint>right_gripper_finger1_finger_tip_joint</mimicJoint>
            <multiplier>-1.0</multiplier>
            <offset>0.0</offset>
        </plugin>
        <plugin filename="libroboticsgroup_gazebo_mimic_joint_plugin.so" name="right_mimic_robotiq_85_5">
            <joint>right_gripper_finger1_joint</joint>
            <mimicJoint>right_gripper_finger2_finger_tip_joint</mimicJoint>
            <multiplier>-1.0</multiplier>
            <offset>0.0</offset>
        </plugin>
    </gazebo>
    <transmission name="trans_right_shoulder_pan_joint">
        <type>transmission_interface/SimpleTransmission</type>
        <joint name="right_shoulder_pan_joint">
            <hardwareInterface>hardware_interface/EffortJointInterface</hardwareInterface>
        </joint>
        <actuator name="right_shoulder_pan_joint_motor">
            <hardwareInterface>hardware_interface/EffortJointInterface</hardwareInterface>
            <mechanicalReduction>1</mechanicalReduction>
        </actuator>
    </transmission>
    <transmission name="trans_right_shoulder_lift_joint">
        <type>transmission_interface/SimpleTransmission</type>
        <joint name="right_shoulder_lift_joint">
            <hardwareInterface>hardware_interface/EffortJointInterface</hardwareInterface>
        </joint>
        <actuator name="right_shoulder_lift_joint_motor">
            <hardwareInterface>hardware_interface/EffortJointInterface</hardwareInterface>
            <mechanicalReduction>1</mechanicalReduction>
        </actuator>
    </transmission>
    <transmission name="trans_right_elbow_joint">
        <type>transmission_interface/SimpleTransmission</type>
        <joint name="right_elbow_joint">
            <hardwareInterface>hardware_interface/EffortJointInterface</hardwareInterface>
        </joint>
        <actuator name="right_elbow_joint_motor">
            <hardwareInterface>hardware_interface/EffortJointInterface</hardwareInterface>
            <mechanicalReduction>1</mechanicalReduction>
        </actuator>
    </transmission>
    <transmission name="trans_right_wrist_1_joint">
        <type>transmission_interface/SimpleTransmission</type>
        <joint name="right_wrist_1_joint">
            <hardwareInterface>hardware_interface/EffortJointInterface</hardwareInterface>
        </joint>
        <actuator name="right_wrist_1_joint_motor">
            <hardwareInterface>hardware_interface/EffortJointInterface</hardwareInterface>
            <mechanicalReduction>1</mechanicalReduction>
        </actuator>
    </transmission>
    <transmission name="trans_right_wrist_2_joint">
        <type>transmission_interface/SimpleTransmission</type>
        <joint name="right_wrist_2_joint">
            <hardwareInterface>hardware_interface/EffortJointInterface</hardwareInterface>
        </joint>
        <actuator name="right_wrist_2_joint_motor">
            <hardwareInterface>hardware_interface/EffortJointInterface</hardwareInterface>
            <mechanicalReduction>1</mechanicalReduction>
        </actuator>
    </transmission>
    <transmission name="trans_right_wrist_3_joint">
        <type>transmission_interface/SimpleTransmission</type>
        <joint name="right_wrist_3_joint">
            <hardwareInterface>hardware_interface/EffortJointInterface</hardwareInterface>
        </joint>
        <actuator name="right_wrist_3_joint_motor">
            <hardwareInterface>hardware_interface/EffortJointInterface</hardwareInterface>
            <mechanicalReduction>1</mechanicalReduction>
        </actuator>
    </transmission>
    <transmission name="trans_right_gripper_finger1_joint">
        <type>transmission_interface/SimpleTransmission</type>
        <joint name="right_gripper_finger1_joint">
            <hardwareInterface>hardware_interface/EffortJointInterface</hardwareInterface>
        </joint>
        <actuator name="right_gripper_finger1_joint_motor">
            <hardwareInterface>hardware_interface/EffortJointInterface</hardwareInterface>
            <mechanicalReduction>1</mechanicalReduction>
        </actuator>
    </transmission>
    <transmission name="trans_right_gripper_finger2_joint">
        <type>transmission_interface/SimpleTransmission</type>
        <joint name="right_gripper_finger2_joint">
            <hardwareInterface>hardware_interface/EffortJointInterface</hardwareInterface>
        </joint>
        <actuator name="right_gripper_finger2_joint_motor">
            <hardwareInterface>hardware_interface/EffortJointInterface</hardwareInterface>
            <mechanicalReduction>1</mechanicalReduction>
        </actuator>
    </transmission>
    <transmission name="trans_right_gripper_finger1_inner_knuckle_joint">
        <type>transmission_interface/SimpleTransmission</type>
        <joint name="right_gripper_finger1_inner_knuckle_joint">
            <hardwareInterface>hardware_interface/EffortJointInterface</hardwareInterface>
        </joint>
        <actuator name="right_gripper_finger1_inner_knuckle_joint_motor">
            <hardwareInterface>hardware_interface/EffortJointInterface</hardwareInterface>
            <mechanicalReduction>1</mechanicalReduction>
        </actuator>
    </transmission>
    <transmission name="trans_right_gripper_finger2_inner_knuckle_joint">
        <type>transmission_interface/SimpleTransmission</type>
        <joint name="right_gripper_finger2_inner_knuckle_joint">
            <hardwareInterface>hardware_interface/EffortJointInterface</hardwareInterface>
        </joint>
        <actuator name="right_gripper_finger2_inner_knuckle_joint_motor">
            <hardwareInterface>hardware_interface/EffortJointInterface</hardwareInterface>
            <mechanicalReduction>1</mechanicalReduction>
        </actuator>
    </transmission>
    <transmission name="trans_right_gripper_finger1_finger_tip_joint">
        <type>transmission_interface/SimpleTransmission</type>
        <joint name="right_gripper_finger1_finger_tip_joint">
            <hardwareInterface>hardware_interface/EffortJointInterface</hardwareInterface>
        </joint>
        <actuator name="right_gripper_finger1_finger_tip_joint_motor">
            <hardwareInterface>hardware_interface/EffortJointInterface</hardwareInterface>
            <mechanicalReduction>1</mechanicalReduction>
        </actuator>
    </transmission>
    <transmission name="trans_right_gripper_finger2_finger_tip_joint">
        <type>transmission_interface/SimpleTransmission</type>
        <joint name="right_gripper_finger2_finger_tip_joint">
            <hardwareInterface>hardware_interface/EffortJointInterface</hardwareInterface>
        </joint>
        <actuator name="right_gripper_finger2_finger_tip_joint_motor">
            <hardwareInterface>hardware_interface/EffortJointInterface</hardwareInterface>
            <mechanicalReduction>1</mechanicalReduction>
        </actuator>
    </transmission>
    <gazebo>
        <plugin name="gazebo_ros_control" filename="libgazebo_ros_control.so">
            <robotNamespace>/</robotNamespace>
        </plugin>
    </gazebo>
</robot>